Workbook

Sheet Notes
A1: MBGL: medium/long-term growth, margin & FCF outlook (chart data)
A3: Purpose: chart-ready tables for the medium-term (2028-30) and long-term (2030+) outlook. Every table is laid out as a clean block (labels in column A, series in columns) so Excel charts can be built directly from it; ready-made charts are on the "Charts" tab.
A4: Colour code: blue = input/assumption (change freely), black = formula, green = link to another tab.
A5: Tiers: [D] disclosed in filings; [IR] management statement (Investor Day 12-May-26, Q2-26 call 7-Aug-26, Goldman Sachs conference 10-Sep-26); [C] computed; [E] analyst estimate (inference, not guidance).
A6: What management has guided: only the group medium-term framework (7.5-10% organic, core 5-7% "majority in value" + new products 1-2% + international 1-2%; 50bp+ annual margin expansion from 2028; 8-11% Adj. EBITDA growth; 25-27% medium-term effective tax rate; SBC 3-4% of revenue; capex "relatively low"; 75%+ of FCF returned; ~2.5x gross leverage). No segment targets and nothing beyond ~2030.
A7: Segment driver splits (CARFAX, B2B), the 2026-2040 projection and long-run margins are [E]. Price evidence: Q2-26 10-Q "price increases of approximately $16 million and $36 million" (Q2/6M) vs new business ~$8m/$20m [D]; CARFAX subscription growth "primarily driven by price increases", B2B "primarily due to continued new business growth" [D].
A8: Adjusted EBITDA adds back stock-based compensation (SBC). "After SBC" rows treat SBC as a real cost.
A9: Cash tax = ETR x (EBITDA - one-offs - SBC - depreciation - interest) + (cash-tax gap $89m - ETR x $296m non-deductible IHS Markit deal amortization) while the amortization lasts (to 2037). The $89m is cash tax above the book provision (CFO); it is a book/cash difference, so cash tax does not fall when it ends.
A10: Peer metrics on the Peers tab are approximate from general knowledge and NOT verified against filings in this project; replace before external use.
A11: FY23-25 actuals: Form 10/A carve-out [D]. IHS Markit Transportation FY14-21: IHS Markit 10-Ks [D] (Nov FYE; includes Maritime & Trade; not comparable with the carve-out).

Sheet Group Framework
A1: Group medium-term growth framework (2028+, "target range every year") [IR]
A3: Component (% organic growth p.a.) | B3: Low | C3: High | D3: Mid | E3: Management statement / source
A4: Core (price/value + volume) | B4: 0.05 | C4: 0.07 | D4: =AVERAGE(B4:C4) | E4: "the 5%-7% revenue growth visibility that we typically have every year"; "value plus volume ... the majority of that is in value" (CFO, Investor Day)
A5: New products | B5: 0.01 | C5: 0.02 | D5: =AVERAGE(B5:C5) | E5: Listings/Showroom, CARFAX for Life, Data Studio/FAST/PIQ, AI products (GS conference)
A6: International | B6: 0.01 | C6: 0.02 | D6: =AVERAGE(B6:C6) | E6: Canada largest; Germany/Italy/Spain/Poland; Chinese OEMs; India. "More mid-to-long term" (GS conference)
A7: Sum of components | B7: =SUM(B4:B6) | C7: =SUM(C4:C6) | D7: =SUM(D4:D6) | E7: Components sum to 7-11%; management states the total as 7.5-10%
A8: Stated organic revenue target | B8: 0.075 | C8: 0.1 | D8: =AVERAGE(B8:C8) | E8: "We are targeting 7.5%-10% organic growth in the medium term"; medium term = "2028 and beyond" (CFO)
A9: Organic Adj. EBITDA growth target | B9: 0.08 | C9: 0.11 | D9: =AVERAGE(B9:C9) | E9: "8% to 11% annual organic adjusted EBITDA growth" (CFO)
A10: Annual Adj. EBITDA margin expansion | B10: 0.005 | E10: "50 basis point margin expansion or more" after the reset; full 50bp "not ... until 2028" (CFO)
A13: Long-term opportunity statements [IR] ($m unless stated)
A14: Opportunity | B14: Today | C14: Target / size | D14: Today as % of target | E14: Statement
A15: B2B addressable market ($m) | B15: 600 | C15: 18000 | D15: =B15/C15 | E15: B2B >$600m revenue; "$6 billion addressable market, about 10% market share ... path to an $18 billion opportunity" (LaFeir)
A16: US listings market ($m; CARFAX share <10%) | B16: 300 | C16: 3000 | D16: =B16/C16 | E16: "north of $3 billion ... not even at 10% of that yet" (Eager, GS). Today = 10% ceiling
A17: CARFAX for Life, US & Canada ($m) | B17: 53 | C17: 150 | D17: =B17/C17 | E17: "His goal in the U.S. and Canada is not $53 million, it's $150 million" (Eager)
A18: CARFAX for Life, global ($m) | B18: 53 | C18: 1000 | D18: =B18/C18 | E18: "... and it's $1 billion globally" (Eager)

Sheet CARFAX Drivers
A1: CARFAX: medium-term (2028-30) and long-term (2030+) growth drivers [E]
A3: Driver (pt of segment growth p.a.) [E] | B3: MT low | C3: MT mid | D3: MT high | E3: LT low | F3: LT mid | G3: LT high | H3: Price? (1=yes) | I3: Basis
A4: Price / value on existing dealer base | B4: 4 | C4: 5 | D4: 6 | E4: 4 | F4: 4.5 | G4: 5 | H4: 1 | I4: 10-Q: CARFAX subscription growth "primarily driven by price increases" [D]; 6M-26 company price ~$36m = at most ~6% of CARFAX revenue [C]; "report as % of car price continues to decline" (Fredericks)
A5: Dealer count (rooftops) | B5: 0 | C5: 0.5 | D5: 1 | E5: 0 | F5: 0 | G5: 0.5 | H5: 0 | I5: Franchise "highly pinned"; ~40k US dealers; small-independent churn and AutoCheck switching (expert calls, D16)
A6: Products per dealer (attach / upsell) | B6: 1 | C6: 1.5 | D6: 2 | E6: 0.5 | F6: 1 | G6: 1.5 | H6: 0 | I6: "Most dealers are only on 1.5 products ... three or four or five" (Fredericks)
A7: Listings & Showroom | B7: 1 | C7: 1.5 | D7: 2 | E7: 1 | F7: 1 | G7: 2 | H7: 0 | I7: <10% share of a >$3bn US market; "more immediate" 12-18 month lever (Eager, GS)
A8: International (Canada, Europe) | B8: 0.5 | C8: 1 | D8: 2 | E8: 0.5 | F8: 1 | G8: 3 | H8: 0 | I8: Germany launched Jul-26, plus Italy/Spain; global opportunity large but unproven
A9: Insurers & lenders (per-VIN) | B9: 0.5 | C9: 0.5 | D9: 0.5 | E9: 0.5 | F9: 0.5 | G9: 0.5 | H9: 0 | I9: Per-VIN pricing up 3-8% (experts); underwriting volumes cyclical
A10: Segment growth (sum of drivers) | B10: =SUM(B4:B9) | C10: =SUM(C4:C9) | D10: =SUM(D4:D9) | E10: =SUM(E4:E9) | F10: =SUM(F4:F9) | G10: =SUM(G4:G9) | I10: Low/high totals are extreme cases (every driver at its low/high); use the mid case
A11: of which price (pt) | B11: =SUMPRODUCT(B4:B9,$H$4:$H$9) | C11: =SUMPRODUCT(C4:C9,$H$4:$H$9) | D11: =SUMPRODUCT(D4:D9,$H$4:$H$9) | E11: =SUMPRODUCT(E4:E9,$H$4:$H$9) | F11: =SUMPRODUCT(F4:F9,$H$4:$H$9) | G11: =SUMPRODUCT(G4:G9,$H$4:$H$9)
A12: of which volume / other (pt) | B12: =B10-B11 | C12: =C10-C11 | D12: =D10-D11 | E12: =E10-E11 | F12: =F10-F11 | G12: =G10-G11
A13: Price share of segment growth | B13: =IF(B10=0,0,B11/B10) | C13: =IF(C10=0,0,C11/C10) | D13: =IF(D10=0,0,D11/D10) | E13: =IF(E10=0,0,E11/E10) | F13: =IF(F10=0,0,F11/F10) | G13: =IF(G10=0,0,G11/G10)
A15: Required growth: with B2B at 4-6% and ~35% of revenue, CARFAX must grow ~9-12% for the group to reach 7.5-10% [C]. History [D]: FY24 +12%, FY25 +10%, Q2-26 +8%. Analogue: Auto Trader UK, where flat retailer count and ~6-8% ARPR growth drive almost all growth (approximate, not verified).

Sheet B2B Drivers
A1: B2B: medium-term (2028-30) and long-term (2030+) growth drivers [E]
A3: Driver (pt of segment growth p.a.) [E] | B3: MT low | C3: MT mid | D3: MT high | E3: LT low | F3: LT mid | G3: LT high | H3: Price? (1=yes) | I3: Basis
A4: Price / escalators | B4: 1 | C4: 1.5 | D4: 2 | E4: 1 | F4: 1.5 | G4: 2 | H4: 1 | I4: Never disclosed; planning competitor is a "low-cost alternative" (LaFeir), so inflation-type pricing assumed
A5: New business / penetration | B5: 1.5 | C5: 2 | D5: 3 | E5: 1 | F5: 1.5 | G5: 2 | H5: 0 | I5: 10-Q: B2B growth "primarily due to continued new business growth" [D]; "<50% penetrated" with top-40 OEMs (Eager)
A6: automotiveMastermind | B6: 0.5 | C6: 1 | D6: 1.5 | E6: 0.5 | F6: 0.5 | G6: 1 | H6: 0 | I6: "Growing at double digits" (LaFeir); 3,200 dealers
A7: New products (FAST, PIQ, Data Studio) | B7: 0 | C7: 0.5 | D7: 1 | E7: 0.5 | F7: 1 | G7: 2 | H7: 0 | I7: All "in their early stages" (Eager, GS)
A8: International (Chinese OEMs, India) | B8: 0 | C8: 0.5 | D8: 1 | E8: 0.5 | F8: 0.5 | G8: 1 | H8: 0 | I8: Investor Day strategy
A9: Recall / transactional | B9: -1 | C9: -0.5 | D9: 0 | E9: -0.5 | F9: 0 | G9: 0.5 | H9: 0 | I9: Recall the "one minor exception" to growth (CFO); planning projects cyclical (Q2-26)
A10: Segment growth (sum of drivers) | B10: =SUM(B4:B9) | C10: =SUM(C4:C9) | D10: =SUM(D4:D9) | E10: =SUM(E4:E9) | F10: =SUM(F4:F9) | G10: =SUM(G4:G9) | I10: Low/high totals are extreme cases (every driver at its low/high); use the mid case
A11: of which price (pt) | B11: =SUMPRODUCT(B4:B9,$H$4:$H$9) | C11: =SUMPRODUCT(C4:C9,$H$4:$H$9) | D11: =SUMPRODUCT(D4:D9,$H$4:$H$9) | E11: =SUMPRODUCT(E4:E9,$H$4:$H$9) | F11: =SUMPRODUCT(F4:F9,$H$4:$H$9) | G11: =SUMPRODUCT(G4:G9,$H$4:$H$9)
A12: of which volume / other (pt) | B12: =B10-B11 | C12: =C10-C11 | D12: =D10-D11 | E12: =E10-E11 | F12: =F10-F11 | G12: =G10-G11
A13: Price share of segment growth | B13: =IF(B10=0,0,B11/B10) | C13: =IF(C10=0,0,C11/C10) | D13: =IF(D10=0,0,D11/D10) | E13: =IF(E10=0,0,E11/E10) | F13: =IF(F10=0,0,F11/F10) | G13: =IF(G10=0,0,G11/G10)
A15: History [D]: FY24 +3%, FY25 +6%, Q1-26 +8%, Q2-26 +4% (subscription +6%, transactional -4%). Growth above ~6% would require the "$18bn opportunity" to convert; nothing in the record shows it yet.

Sheet Projection
A1: Segment revenue, margin and FCF projection, FY2023A-FY2040E ($m) [A = actual, E = estimate]
A3: $m | B3: FY2023A | C3: FY2024A | D3: FY2025A | E3: FY2026E | F3: FY2027E | G3: FY2028E | H3: FY2029E | I3: FY2030E | J3: FY2031E | K3: FY2032E | L3: FY2033E | M3: FY2034E | N3: FY2035E | O3: FY2036E | P3: FY2037E | Q3: FY2038E | R3: FY2039E | S3: FY2040E | T3: Basis
A4: Assumptions (blue = change freely)
A5: CARFAX organic growth | E5: 0.085 | F5: 0.09 | G5: 0.1 | H5: 0.1 | I5: 0.1 | J5: 0.096 | K5: 0.092 | L5: 0.088 | M5: 0.084 | N5: 0.08 | O5: 0.08 | P5: 0.08 | Q5: 0.08 | R5: 0.08 | S5: 0.08 | T5: [E] FY26 from guidance mid; 2028-30 = CARFAX Drivers MT mid; fades to LT mid (8%)
A6: B2B organic growth | E6: 0.05 | F6: 0.05 | G6: 0.05 | H6: 0.05 | I6: 0.05 | J6: 0.05 | K6: 0.05 | L6: 0.05 | M6: 0.05 | N6: 0.05 | O6: 0.05 | P6: 0.05 | Q6: 0.05 | R6: 0.05 | S6: 0.05 | T6: [E] B2B Drivers MT/LT mid (~5%)
A7: CARFAX price contribution (pt) | E7: 0.06 | F7: 0.05 | G7: 0.05 | H7: 0.05 | I7: 0.05 | J7: 0.045 | K7: 0.045 | L7: 0.045 | M7: 0.045 | N7: 0.045 | O7: 0.045 | P7: 0.045 | Q7: 0.045 | R7: 0.045 | S7: 0.045 | T7: [E] FY26 ~6% upper bound from 10-Q price $; then CARFAX Drivers price row
A8: B2B price contribution (pt) | E8: 0.015 | F8: 0.015 | G8: 0.015 | H8: 0.015 | I8: 0.015 | J8: 0.015 | K8: 0.015 | L8: 0.015 | M8: 0.015 | N8: 0.015 | O8: 0.015 | P8: 0.015 | Q8: 0.015 | R8: 0.015 | S8: 0.015 | T8: [E] B2B Drivers price row
A9: Group Adj. EBITDA margin | E9: 0.401 | F9: 0.395 | G9: 0.4 | H9: 0.405 | I9: 0.41 | J9: 0.416 | K9: 0.422 | L9: 0.428 | M9: 0.434 | N9: 0.44 | O9: 0.444 | P9: 0.448 | Q9: 0.452 | R9: 0.456 | S9: 0.46 | T9: [IR] FY26 guide mid ~40.1%; FY27 39.5% (FY25 40.6% - 150bp standalone + efficiency); +50bp/yr 2028-30 [IR]; +60bp/yr 2031-35, +40bp/yr 2036-40 [E]
A10: SBC % of revenue | E10: 0.019 | F10: 0.03 | G10: 0.035 | H10: 0.035 | I10: 0.035 | J10: 0.035 | K10: 0.035 | L10: 0.035 | M10: 0.035 | N10: 0.035 | O10: 0.035 | P10: 0.035 | Q10: 0.035 | R10: 0.035 | S10: 0.035 | T10: [IR] ~1% rising to 3-4%; FY26 = H1 actual $9m + H2 ramp [E]
A11: Effective tax rate | E11: 0.2925 | F11: 0.28 | G11: 0.27 | H11: 0.26 | I11: 0.26 | J11: 0.26 | K11: 0.26 | L11: 0.26 | M11: 0.26 | N11: 0.26 | O11: 0.26 | P11: 0.26 | Q11: 0.26 | R11: 0.26 | S11: 0.26 | T11: [IR] FY26 GAAP 28-30.5%; medium-term 25-27% (CFO, Investor Day)
A12: Recurring capex % of revenue | E12: 0.014 | F12: 0.014 | G12: 0.014 | H12: 0.014 | I12: 0.014 | J12: 0.014 | K12: 0.014 | L12: 0.014 | M12: 0.014 | N12: 0.014 | O12: 0.014 | P12: 0.014 | Q12: 0.014 | R12: 0.014 | S12: 0.014 | T12: [D] FY23-25 0.9-1.4%; "relatively low" [IR]
A13: Tax-deductible depreciation % of revenue | E13: 0.008 | F13: 0.008 | G13: 0.008 | H13: 0.008 | I13: 0.008 | J13: 0.008 | K13: 0.008 | L13: 0.008 | M13: 0.008 | N13: 0.008 | O13: 0.008 | P13: 0.008 | Q13: 0.008 | R13: 0.008 | S13: 0.008 | T13: [D] FY25 depreciation $14m
A14: Working capital inflow % of revenue increase | E14: 0.1 | F14: 0.1 | G14: 0.1 | H14: 0.1 | I14: 0.1 | J14: 0.1 | K14: 0.1 | L14: 0.1 | M14: 0.1 | N14: 0.1 | O14: 0.1 | P14: 0.1 | Q14: 0.1 | R14: 0.1 | S14: 0.1 | T14: [C] deferred-revenue inflow; FY25 ~$23m on +$137m revenue
A15: Gross leverage (Debt / Adj. EBITDA) | G15: 2.5 | H15: 2.5 | I15: 2.5 | J15: 2.5 | K15: 2.5 | L15: 2.5 | M15: 2.5 | N15: 2.5 | O15: 2.5 | P15: 2.5 | Q15: 2.5 | R15: 2.5 | S15: 2.5 | T15: [IR] target ~2.5x gross; FY26-27 = $2.0bn bonds (non-prepayable)
A16: Cash interest rate on debt | G16: 0.056 | H16: 0.056 | I16: 0.056 | J16: 0.056 | K16: 0.056 | L16: 0.056 | M16: 0.056 | N16: 0.056 | O16: 0.056 | P16: 0.056 | Q16: 0.056 | R16: 0.056 | S16: 0.056 | T16: [D] 5.74% weighted incl. fee amortization; ~5.6% cash coupon [E]
A17: Non-deductible deal amortization | E17: 296 | F17: 296 | G17: 296 | H17: 296 | I17: 296 | J17: 296 | K17: 296 | L17: 296 | M17: 296 | N17: 296 | O17: 296 | P17: 296 | Q17: 0 | R17: 0 | S17: 0 | T17: [D] FY25 amortization of intangibles $296m; ~12 years from 2026 [IR]
A18: Cash tax above book provision | E18: 89 | F18: 89 | G18: 89 | H18: 89 | I18: 89 | J18: 89 | K18: 89 | L18: 89 | M18: 89 | N18: 89 | O18: 89 | P18: 89 | Q18: 0 | R18: 0 | S18: 0 | T18: [IR] "for the next 12 years, cash taxes will be approximately $89 million higher than our tax provision"
A20: Segment revenue
A21: CARFAX revenue | B21: 928 | C21: 1039 | D21: 1142 | E21: =D21*(1+E5) | F21: =E21*(1+F5) | G21: =F21*(1+G5) | H21: =G21*(1+H5) | I21: =H21*(1+I5) | J21: =I21*(1+J5) | K21: =J21*(1+K5) | L21: =K21*(1+L5) | ... S21: =R21*(1+S5) | T21: [D] Form 10/A FY23-25
A22: B2B revenue | B22: 557 | C22: 574 | D22: 608 | E22: =D22*(1+E6) | F22: =E22*(1+F6) | G22: =F22*(1+G6) | H22: =G22*(1+H6) | I22: =H22*(1+I6) | J22: =I22*(1+J6) | K22: =J22*(1+K6) | L22: =K22*(1+L6) | ... S22: =R22*(1+S6) | T22: [D] Form 10/A FY23-25
A23: Group revenue | B23: =B21+B22 | C23: =C21+C22 | D23: =D21+D22 | E23: =E21+E22 | F23: =F21+F22 | G23: =G21+G22 | H23: =H21+H22 | I23: =I21+I22 | ... S23: =S21+S22 | T23: [C]
A24: Group revenue growth | C24: =C23/B23-1 | D24: =D23/C23-1 | E24: =E23/D23-1 | F24: =F23/E23-1 | G24: =G23/F23-1 | H24: =H23/G23-1 | I24: =I23/H23-1 | J24: =J23/I23-1 | ... S24: =S23/R23-1 | T24: [C]
A25: CARFAX growth (actual / assumed) | C25: =C21/B21-1 | D25: =D21/C21-1 | E25: =E21/D21-1 | F25: =F21/E21-1 | G25: =G21/F21-1 | H25: =H21/G21-1 | I25: =I21/H21-1 | J25: =J21/I21-1 | ... S25: =S21/R21-1 | T25: [C]
A26: B2B growth (actual / assumed) | C26: =C22/B22-1 | D26: =D22/C22-1 | E26: =E22/D22-1 | F26: =F22/E22-1 | G26: =G22/F22-1 | H26: =H22/G22-1 | I26: =I22/H22-1 | J26: =J22/I22-1 | ... S26: =S22/R22-1 | T26: [C]
A27: CARFAX share of revenue | B27: =B21/B23 | C27: =C21/C23 | D27: =D21/D23 | E27: =E21/E23 | F27: =F21/F23 | G27: =G21/G23 | H27: =H21/H23 | I27: =I21/I23 | ... S27: =S21/S23 | T27: [C]
A28: B2B share of revenue | B28: =B22/B23 | C28: =C22/C23 | D28: =D22/D23 | E28: =E22/E23 | F28: =F22/F23 | G28: =G22/G23 | H28: =H22/H23 | I28: =I22/I23 | ... S28: =S22/S23 | T28: [C]
A29: Group growth from price (pt) | E29: =E7*D21/D23+E8*D22/D23 | F29: =F7*E21/E23+F8*E22/E23 | G29: =G7*F21/F23+G8*F22/F23 | H29: =H7*G21/G23+H8*G22/G23 | I29: =I7*H21/H23+I8*H22/H23 | J29: =J7*I21/I23+J8*I22/I23 | K29: =K7*J21/J23+K8*J22/J23 | L29: =L7*K21/K23+L8*K22/K23 | ... S29: =S7*R21/R23+S8*R22/R23 | T29: [C] segment price pt weighted by prior-year mix
A30: Group growth from volume / other (pt) | E30: =E24-E29 | F30: =F24-F29 | G30: =G24-G29 | H30: =H24-H29 | I30: =I24-I29 | J30: =J24-J29 | K30: =K24-K29 | L30: =L24-L29 | ... S30: =S24-S29 | T30: [C]
A31: Price share of group growth | E31: =E29/E24 | F31: =F29/F24 | G31: =G29/G24 | H31: =H29/H24 | I31: =I29/I24 | J31: =J29/J24 | K31: =K29/K24 | L31: =L29/L24 | ... S31: =S29/S24 | T31: [C] H1-26 actual ~56% [D/C]
A33: Margins
A34: Adj. EBITDA | B34: 598 | C34: 658 | D34: 711 | E34: =E23*E9 | F34: =F23*F9 | G34: =G23*G9 | H34: =H23*H9 | I34: =I23*I9 | J34: =J23*J9 | K34: =K23*K9 | L34: =L23*L9 | ... S34: =S23*S9 | T34: [D] FY23-25; FY26 guide mid $752.5m
A35: Adj. EBITDA margin | B35: =B34/B23 | C35: =C34/C23 | D35: =D34/D23 | E35: =E34/E23 | F35: =F34/F23 | G35: =G34/G23 | H35: =H34/H23 | I35: =I34/I23 | ... S35: =S34/S23 | T35: [C]
A36: Stock-based compensation | B36: 20 | C36: 28 | D36: 22 | E36: =E23*E10 | F36: =F23*F10 | G36: =G23*G10 | H36: =H23*H10 | I36: =I23*I10 | J36: =J23*J10 | K36: =K23*K10 | L36: =L23*L10 | ... S36: =S23*S10 | T36: [D] FY23-25 cash flow statement
A37: Adj. EBITDA margin after SBC | B37: =(B34-B36)/B23 | C37: =(C34-C36)/C23 | D37: =(D34-D36)/D23 | E37: =(E34-E36)/E23 | F37: =(F34-F36)/F23 | G37: =(G34-G36)/G23 | H37: =(H34-H36)/H23 | I37: =(I34-I36)/I23 | ... S37: =(S34-S36)/S23 | T37: [C]
A38: CARFAX segment Adj. EBITDA margin | B38: 0.45474138 | C38: 0.45813282 | D38: 0.46935201 | T38: [D/C] segment Adj. EBITDA 422/476/536
A39: B2B segment Adj. EBITDA margin | B39: 0.34290844 | C39: 0.35365854 | D39: 0.32401316 | T39: [D/C] segment Adj. EBITDA 191/203/197
A41: Cash flow (FY23-25 actual bridge; FY26+ estimate)
A42: One-offs, expensed | B42: -30 | C42: -23 | D42: -40 | E42: -25 | F42: -25 | G42: =0 | H42: =0 | I42: =0 | J42: =0 | K42: =0 | L42: =0 | M42: =0 | N42: =0 | ... S42: =0 | T42: [D] FY23-25; FY26-27 = 50% expensed x ~$50m/yr of ~$100m spin cost [IR]
A43: Gross debt (year end) | E43: 2000 | F43: 2000 | G43: =MAX(2000,G15*G34) | H43: =MAX(2000,H15*H34) | I43: =MAX(2000,I15*I34) | J43: =MAX(2000,J15*J34) | K43: =MAX(2000,K15*K34) | L43: =MAX(2000,L15*L34) | M43: =MAX(2000,M15*M34) | N43: =MAX(2000,N15*N34) | ... S43: =MAX(2000,S15*S34) | T43: [D] $2.0bn senior notes; then leverage x EBITDA (buybacks funded)
A44: Cash interest | B44: -17 | C44: -15 | D44: -13 | E44: -65 | F44: -112 | G44: =-G16*G43 | H44: =-H16*H43 | I44: =-I16*I43 | J44: =-J16*J43 | K44: =-K16*K43 | L44: =-L16*L43 | M44: =-M16*M43 | N44: =-N16*N43 | ... S44: =-S16*S43 | T44: [D] FY23-25 related-party; FY26 ~$5m + $60m Q4 coupon [IR]; FY27 5.6% x $2.0bn
...

Sheet Chart Data
A1: Chart-ready series (linked to Projection; green = link)
A3: Series | B3: FY2023 | C3: FY2024 | D3: FY2025 | E3: FY2026 | F3: FY2027 | G3: FY2028 | H3: FY2029 | I3: FY2030 | J3: FY2031 | K3: FY2032 | L3: FY2033 | M3: FY2034 | N3: FY2035 | O3: FY2036 | P3: FY2037 | Q3: FY2038 | R3: FY2039 | S3: FY2040
A4: Revenue mix ($m)
A5: CARFAX | B5: =IF(Projection!B21="",NA(),Projection!B21) | C5: =IF(Projection!C21="",NA(),Projection!C21) | D5: =IF(Projection!D21="",NA(),Projection!D21) | E5: =IF(Projection!E21="",NA(),Projection!E21) | F5: =IF(Projection!F21="",NA(),Projection!F21) | G5: =IF(Projection!G21="",NA(),Projection!G21) | H5: =IF(Projection!H21="",NA(),Projection!H21) | I5: =IF(Projection!I21="",NA(),Projection!I21) | ... S5: =IF(Projection!S21="",NA(),Projection!S21)
A6: B2B | B6: =IF(Projection!B22="",NA(),Projection!B22) | C6: =IF(Projection!C22="",NA(),Projection!C22) | D6: =IF(Projection!D22="",NA(),Projection!D22) | E6: =IF(Projection!E22="",NA(),Projection!E22) | F6: =IF(Projection!F22="",NA(),Projection!F22) | G6: =IF(Projection!G22="",NA(),Projection!G22) | H6: =IF(Projection!H22="",NA(),Projection!H22) | I6: =IF(Projection!I22="",NA(),Projection!I22) | ... S6: =IF(Projection!S22="",NA(),Projection!S22)
A8: Growth (%)
A9: Group | B9: =IF(Projection!B24="",NA(),Projection!B24) | C9: =IF(Projection!C24="",NA(),Projection!C24) | D9: =IF(Projection!D24="",NA(),Projection!D24) | E9: =IF(Projection!E24="",NA(),Projection!E24) | F9: =IF(Projection!F24="",NA(),Projection!F24) | G9: =IF(Projection!G24="",NA(),Projection!G24) | H9: =IF(Projection!H24="",NA(),Projection!H24) | I9: =IF(Projection!I24="",NA(),Projection!I24) | ... S9: =IF(Projection!S24="",NA(),Projection!S24)
A10: CARFAX | B10: =IF(Projection!B25="",NA(),Projection!B25) | C10: =IF(Projection!C25="",NA(),Projection!C25) | D10: =IF(Projection!D25="",NA(),Projection!D25) | E10: =IF(Projection!E25="",NA(),Projection!E25) | F10: =IF(Projection!F25="",NA(),Projection!F25) | G10: =IF(Projection!G25="",NA(),Projection!G25) | H10: =IF(Projection!H25="",NA(),Projection!H25) | I10: =IF(Projection!I25="",NA(),Projection!I25) | ... S10: =IF(Projection!S25="",NA(),Projection!S25)
A11: B2B | B11: =IF(Projection!B26="",NA(),Projection!B26) | C11: =IF(Projection!C26="",NA(),Projection!C26) | D11: =IF(Projection!D26="",NA(),Projection!D26) | E11: =IF(Projection!E26="",NA(),Projection!E26) | F11: =IF(Projection!F26="",NA(),Projection!F26) | G11: =IF(Projection!G26="",NA(),Projection!G26) | H11: =IF(Projection!H26="",NA(),Projection!H26) | I11: =IF(Projection!I26="",NA(),Projection!I26) | ... S11: =IF(Projection!S26="",NA(),Projection!S26)
A13: Group growth: price vs volume (pt)
A14: Price | B14: =IF(Projection!B29="",NA(),Projection!B29) | C14: =IF(Projection!C29="",NA(),Projection!C29) | D14: =IF(Projection!D29="",NA(),Projection!D29) | E14: =IF(Projection!E29="",NA(),Projection!E29) | F14: =IF(Projection!F29="",NA(),Projection!F29) | G14: =IF(Projection!G29="",NA(),Projection!G29) | H14: =IF(Projection!H29="",NA(),Projection!H29) | I14: =IF(Projection!I29="",NA(),Projection!I29) | ... S14: =IF(Projection!S29="",NA(),Projection!S29)
A15: Volume / other | B15: =IF(Projection!B30="",NA(),Projection!B30) | C15: =IF(Projection!C30="",NA(),Projection!C30) | D15: =IF(Projection!D30="",NA(),Projection!D30) | E15: =IF(Projection!E30="",NA(),Projection!E30) | F15: =IF(Projection!F30="",NA(),Projection!F30) | G15: =IF(Projection!G30="",NA(),Projection!G30) | H15: =IF(Projection!H30="",NA(),Projection!H30) | I15: =IF(Projection!I30="",NA(),Projection!I30) | ... S15: =IF(Projection!S30="",NA(),Projection!S30)
A17: Margins (%)
A18: Adj. EBITDA margin | B18: =IF(Projection!B35="",NA(),Projection!B35) | C18: =IF(Projection!C35="",NA(),Projection!C35) | D18: =IF(Projection!D35="",NA(),Projection!D35) | E18: =IF(Projection!E35="",NA(),Projection!E35) | F18: =IF(Projection!F35="",NA(),Projection!F35) | G18: =IF(Projection!G35="",NA(),Projection!G35) | H18: =IF(Projection!H35="",NA(),Projection!H35) | I18: =IF(Projection!I35="",NA(),Projection!I35) | ... S18: =IF(Projection!S35="",NA(),Projection!S35)
A19: Adj. EBITDA margin after SBC | B19: =IF(Projection!B37="",NA(),Projection!B37) | C19: =IF(Projection!C37="",NA(),Projection!C37) | D19: =IF(Projection!D37="",NA(),Projection!D37) | E19: =IF(Projection!E37="",NA(),Projection!E37) | F19: =IF(Projection!F37="",NA(),Projection!F37) | G19: =IF(Projection!G37="",NA(),Projection!G37) | H19: =IF(Projection!H37="",NA(),Projection!H37) | I19: =IF(Projection!I37="",NA(),Projection!I37) | ... S19: =IF(Projection!S37="",NA(),Projection!S37)
A20: FCF margin before SBC | B20: =IF(Projection!B52="",NA(),Projection!B52) | C20: =IF(Projection!C52="",NA(),Projection!C52) | D20: =IF(Projection!D52="",NA(),Projection!D52) | E20: =IF(Projection!E52="",NA(),Projection!E52) | F20: =IF(Projection!F52="",NA(),Projection!F52) | G20: =IF(Projection!G52="",NA(),Projection!G52) | H20: =IF(Projection!H52="",NA(),Projection!H52) | I20: =IF(Projection!I52="",NA(),Projection!I52) | ... S20: =IF(Projection!S52="",NA(),Projection!S52)
A21: FCF margin after SBC | B21: =IF(Projection!B53="",NA(),Projection!B53) | C21: =IF(Projection!C53="",NA(),Projection!C53) | D21: =IF(Projection!D53="",NA(),Projection!D53) | E21: =IF(Projection!E53="",NA(),Projection!E53) | F21: =IF(Projection!F53="",NA(),Projection!F53) | G21: =IF(Projection!G53="",NA(),Projection!G53) | H21: =IF(Projection!H53="",NA(),Projection!H53) | I21: =IF(Projection!I53="",NA(),Projection!I53) | ... S21: =IF(Projection!S53="",NA(),Projection!S53)
A23: FCF ($m)
A24: Adj. EBITDA | B24: =IF(Projection!B34="",NA(),Projection!B34) | C24: =IF(Projection!C34="",NA(),Projection!C34) | D24: =IF(Projection!D34="",NA(),Projection!D34) | E24: =IF(Projection!E34="",NA(),Projection!E34) | F24: =IF(Projection!F34="",NA(),Projection!F34) | G24: =IF(Projection!G34="",NA(),Projection!G34) | H24: =IF(Projection!H34="",NA(),Projection!H34) | I24: =IF(Projection!I34="",NA(),Projection!I34) | ... S24: =IF(Projection!S34="",NA(),Projection!S34)
A25: FCF before SBC | B25: =IF(Projection!B49="",NA(),Projection!B49) | C25: =IF(Projection!C49="",NA(),Projection!C49) | D25: =IF(Projection!D49="",NA(),Projection!D49) | E25: =IF(Projection!E49="",NA(),Projection!E49) | F25: =IF(Projection!F49="",NA(),Projection!F49) | G25: =IF(Projection!G49="",NA(),Projection!G49) | H25: =IF(Projection!H49="",NA(),Projection!H49) | I25: =IF(Projection!I49="",NA(),Projection!I49) | ... S25: =IF(Projection!S49="",NA(),Projection!S49)
A26: FCF after SBC | B26: =IF(Projection!B50="",NA(),Projection!B50) | C26: =IF(Projection!C50="",NA(),Projection!C50) | D26: =IF(Projection!D50="",NA(),Projection!D50) | E26: =IF(Projection!E50="",NA(),Projection!E50) | F26: =IF(Projection!F50="",NA(),Projection!F50) | G26: =IF(Projection!G50="",NA(),Projection!G50) | H26: =IF(Projection!H50="",NA(),Projection!H50) | I26: =IF(Projection!I50="",NA(),Projection!I50) | ... S26: =IF(Projection!S50="",NA(),Projection!S50)

Sheet Peers
A1: Peer benchmarks: medium/long-term growth and margin (APPROXIMATE, not verified)
A3: Company | B3: Ticker | C3: Group | D3: Organic growth low | E3: Organic growth high | F3: Growth mid | G3: EBITDA margin (approx.) | H3: Price share of growth | I3: Relevance
A4: Mobility Global (target) | B4: MBGL | C4: Subject | D4: 0.075 | E4: 0.1 | F4: =AVERAGE(D4:E4) | G4: 0.406 | H4: Majority (~55% H1-26) | I4: Medium-term framework [IR]; FY25 margin [D]
A5: Auto Trader Group | B5: AUTO LN | C5: Dealer-pay marketplace | D5: 0.07 | E5: 0.1 | F5: =AVERAGE(D5:E5) | G5: 0.7 | H5: High (ARPR-led) | I5: Best analogue for mature CARFAX: flat retailer count, ARPR growth
A6: Verisk | B6: VRSK | C6: Data & analytics | D6: 0.07 | E6: 0.08 | F6: =AVERAGE(D6:E6) | G6: 0.55 | H6: Mixed | I6: Contributed data / insurance; data-margin ceiling
A7: CCC Intelligent Solutions | B7: CCCS | C7: Auto data & software | D7: 0.07 | E7: 0.09 | F7: =AVERAGE(D7:E7) | G7: 0.41 | H7: Mixed (cross-sell) | I7: Auto claims, insurers, repairers; B2B analogue
A8: Fair Isaac (Scores) | B8: FICO | C8: Data & analytics | D8: 0.1 | E8: 0.12 | F8: =AVERAGE(D8:E8) | G8: 0.55 | H8: Very high | I8: Limits of pricing power; regulatory backlash risk
A9: Experian | B9: EXPN LN | C9: Credit bureau | D9: 0.05 | E9: 0.08 | F9: =AVERAGE(D9:E9) | G9: 0.37 | H9: Moderate | I9: Owns AutoCheck; contributed-data economics
A10: Equifax | B10: EFX | C10: Credit bureau | D10: 0.05 | E10: 0.08 | F10: =AVERAGE(D10:E10) | G10: 0.33 | H10: Moderate | I10: Contributed-data economics
A11: TransUnion | B11: TRU | C11: Credit bureau | D11: 0.05 | E11: 0.08 | F11: =AVERAGE(D11:E11) | G11: 0.36 | H11: Moderate | I11: Contributed-data economics
A12: CarGurus | B12: CARG | C12: Dealer-pay marketplace | D12: 0.03 | E12: 0.06 | F12: =AVERAGE(D12:E12) | G12: 0.3 | H12: Mixed | I12: Competes for same US dealer budget
A13: Cars.com | B13: CARS | C13: Dealer-pay marketplace | D13: 0.02 | E13: 0.05 | F13: =AVERAGE(D13:E13) | G13: 0.29 | H13: Mixed | I13: Competes for same US dealer budget
A14: REA Group | B14: REA AU | C14: Dominant-brand marketplace | D14: 0.08 | E14: 0.12 | F14: =AVERAGE(D14:E14) | G14: 0.57 | H14: High | I14: Dominant-brand pricing benchmark
A15: Rightmove | B15: RMV LN | C15: Dominant-brand marketplace | D15: 0.07 | E15: 0.1 | F15: =AVERAGE(D15:E15) | G15: 0.7 | H15: High | I15: Dominant-brand pricing benchmark (operating margin)
A17: Peer figures are approximate from general knowledge and NOT verified for this project. Auto Trader and Rightmove are operating margins. Replace with filed figures before external use.

Sheet History
A1: History: IHS Markit Transportation (FY14-21, Nov FYE) and Mobility carve-out (FY23-25) [D]
A3: $m | B3: FY2014 | C3: FY2015 | D3: FY2016 | E3: FY2017 | F3: FY2018 | G3: FY2019 | H3: FY2020 | I3: FY2021 | J3: FY2023 | K3: FY2024 | L3: FY2025
A4: Revenue | B4: 662.6 | C4: 758.4 | D4: 892.8 | E4: 991.6 | F4: 1160.2 | G4: 1246.1 | H4: 1151.6 | I4: 1354.4 | J4: 1485 | K4: 1613 | L4: 1750
A5: Adj. EBITDA | B5: 234.3 | C5: 282.7 | D5: 353.3 | E5: 408.6 | F5: 479.3 | G5: 520.9 | H5: 514.7 | I5: 645 | J5: 598 | K5: 658 | L5: 711
A6: Adj. EBITDA margin | B6: =B5/B4 | C6: =C5/C4 | D6: =D5/D4 | E6: =E5/E4 | F6: =F5/F4 | G6: =G5/G4 | H6: =H5/H4 | I6: =I5/I4 | ... L6: =L5/L4
A7: Basis | B7: IHS Transp. | C7: IHS Transp. | D7: IHS Transp. | E7: IHS Transp. | F7: IHS Transp. | G7: IHS Transp. | H7: IHS Transp. | I7: IHS Transp. | J7: Carve-out | K7: Carve-out | L7: Carve-out
A9: Not comparable across eras: IHS Markit segment EBITDA includes Maritime & Trade (~$100-145m revenue, moved to S&P Global Market Intelligence) and different cost allocations; FY22 (S&P Global, ~10 months) omitted. FY21 S&P Global pro forma Mobility: revenue $1,209m ($1,246m adjusted), adjusted operating profit $492m.

Sheet Charts
A1: Charts (all linked to the data tabs; edit blue inputs and they update)
