Workbook

Sheet Annual Summary
A1: Mobility Global (MBGL): annual summary FY2014–FY2026E. P&L, balance sheet, cash flow and segments
A2: Every historical figure links to the as-reported tab (green). Eras are NOT comparable, so growth is computed only within an era. FY2026E = company guidance midpoint (revenue $1,870–1,885m; Adj. EBITDA $745–760m), not an actual. 1H = six months to 30 June. USD millions.
B4: IHS Markit Transportation segment (Nov-30 FYE) | J4: S&P Global Mobility segment (~10 months) | K4: Mobility Global combined (carve-out) | N4: Guidance (8-K 2026-08-07) | P4: Mobility Global combined (carve-out)
A5: USD millions | B5: FY14 | C5: FY15 | D5: FY16 | E5: FY17 | F5: FY18 | G5: FY19 | H5: FY20 | I5: FY21 | J5: FY22 | K5: FY23 | L5: FY24 | M5: FY25 | N5: FY26E | P5: 1H25 | Q5: 1H26 | R5: Source / basis
A6: Income statement
A7: Revenue | B7: ='Segment History'!B6 | C7: ='Segment History'!C6 | D7: ='Segment History'!D6 | E7: ='Segment History'!E6 | F7: ='Segment History'!F6 | G7: ='Segment History'!G6 | H7: ='Segment History'!H6 | I7: ='Segment History'!I6 | J7: ='Segment History'!J27 | K7: ='IS'!B6 | L7: ='IS'!C6 | M7: ='IS'!D6 | N7: 1877.5 | P7: ='IS'!G6 | Q7: ='IS'!J6 | R7: FY14–21 IHS Markit 10-Ks; FY22 SPGI 10-K (Mar–Dec); FY23+ IS tab; FY26E guide midpoint
A8: Revenue growth y/y | C8: =C7/B7-1 | D8: =D7/C7-1 | E8: =E7/D7-1 | F8: =F7/E7-1 | G8: =G7/F7-1 | H8: =H7/G7-1 | I8: =I7/H7-1 | L8: =L7/K7-1 | M8: =M7/L7-1 | N8: =N7/M7-1 | Q8: =Q7/P7-1 | R8: [C] within era only; FY2026E vs FY2025; 1H26 vs 1H25
A9: Organic growth (as printed) | C9: ='Segment History'!C9 | D9: ='Segment History'!D9 | E9: ='Segment History'!E9 | F9: ='Segment History'!F9 | G9: ='Segment History'!G9 | H9: ='Segment History'!H9 | I9: ='Segment History'!I9 | R9: IHS Markit 10-K growth bridge [D]; MBGL prints no organic growth
A10: Subscription revenue (FY20: IHS "recurring") | H10: ='Segment History'!F69 | J10: ='Segment History'!J29 | K10: ='Segment P&L'!B79 | L10: ='Segment P&L'!C79 | M10: ='Segment P&L'!D79 | P10: ='Segment P&L'!G79 | Q10: ='Segment P&L'!J79 | R10: FY20 IHS decks; FY22 SPGI; FY23+ Segment P&L
A11: Non-subscription revenue (FY20: "non-recurring") | H11: ='Segment History'!F70 | J11: ='Segment History'!J30 | K11: ='Segment P&L'!B80 | L11: ='Segment P&L'!C80 | M11: ='Segment P&L'!D80 | P11: ='Segment P&L'!G80 | Q11: ='Segment P&L'!J80
A12: Subscription share of revenue | H12: =IF(H7=0,"",H10/H7) | J12: =IF(J7=0,"",J10/J7) | K12: =IF(K7=0,"",K10/K7) | L12: =IF(L7=0,"",L10/L7) | M12: =IF(M7=0,"",M10/M7) | P12: =IF(P7=0,"",P10/P7) | Q12: =IF(Q7=0,"",Q10/Q7) | R12: [C]
A13: U.S. revenue | J13: ='Segment History'!J32 | K13: ='Segment P&L'!B81 | L13: ='Segment P&L'!C81 | M13: ='Segment P&L'!D81 | P13: ='Segment P&L'!G81 | Q13: ='Segment P&L'!J81
A14: International revenue | J14: ='Segment History'!J33 | K14: ='Segment P&L'!B82 | L14: ='Segment P&L'!C82 | M14: ='Segment P&L'!D82 | P14: ='Segment P&L'!G82 | Q14: ='Segment P&L'!J82
A15: CARFAX segment revenue | K15: ='Segment P&L'!B6 | L15: ='Segment P&L'!C6 | M15: ='Segment P&L'!D6 | P15: ='Segment P&L'!G6 | Q15: ='Segment P&L'!J6 | R15: Segment P&L tab (Form 10/A; 10-Q)
A16: B2B segment revenue | K16: ='Segment P&L'!B35 | L16: ='Segment P&L'!C35 | M16: ='Segment P&L'!D35 | P16: ='Segment P&L'!G35 | Q16: ='Segment P&L'!J35
A17: CARFAX growth y/y | L17: =L15/K15-1 | M17: =M15/L15-1 | Q17: =Q15/P15-1 | R17: [C] within era only; FY2026E vs FY2025; 1H26 vs 1H25
A18: B2B growth y/y | L18: =L16/K16-1 | M18: =M16/L16-1 | Q18: =Q16/P16-1 | R18: [C] within era only; FY2026E vs FY2025; 1H26 vs 1H25
A19: Operating-related expenses | K19: ='IS'!B7 | L19: ='IS'!C7 | M19: ='IS'!D7 | P19: ='IS'!G7 | Q19: ='IS'!J7 | R19: IS tab
A20: Selling and general expenses | K20: ='IS'!B8 | L20: ='IS'!C8 | M20: ='IS'!D8 | P20: ='IS'!G8 | Q20: ='IS'!J8
A21: Depreciation | K21: ='IS'!B9 | L21: ='IS'!C9 | M21: ='IS'!D9 | P21: ='IS'!G9 | Q21: ='IS'!J9
A22: Amortization of acquired intangibles | K22: ='IS'!B10 | L22: ='IS'!C10 | M22: ='IS'!D10 | P22: ='IS'!G10 | Q22: ='IS'!J10 | R22: IHS Markit merger step-up
A23: Depreciation & amortization (segment total) | J23: ='Segment History'!J37 | R23: FY22 SPGI segment note
A24: Operating profit | J24: ='Segment History'!J34 | K24: ='IS'!B12 | L24: ='IS'!C12 | M24: ='IS'!D12 | P24: ='IS'!G12 | Q24: ='IS'!J12 | R24: FY22 SPGI segment OP; FY23+ IS
A25: Operating margin | J25: =IF(J7=0,"",J24/J7) | K25: =IF(K7=0,"",K24/K7) | L25: =IF(L7=0,"",L24/L7) | M25: =IF(M7=0,"",M24/M7) | P25: =IF(P7=0,"",P24/P7) | Q25: =IF(Q7=0,"",Q24/Q7) | R25: [C]
A26: Interest expense, net | K26: ='IS'!B14 | L26: ='IS'!C14 | M26: ='IS'!D14 | P26: ='IS'!G14 | Q26: ='IS'!J14
A27: Income before taxes | K27: ='IS'!B15 | L27: ='IS'!C15 | M27: ='IS'!D15 | P27: ='IS'!G15 | Q27: ='IS'!J15
A28: Provision for taxes | K28: ='IS'!B16 | L28: ='IS'!C16 | M28: ='IS'!D16 | P28: ='IS'!G16 | Q28: ='IS'!J16
A29: Net income | K29: ='IS'!B17 | L29: ='IS'!C17 | M29: ='IS'!D17 | P29: ='IS'!G17 | Q29: ='IS'!J17 | R29: Carve-out; excludes $2.0bn notes issued May-2026 (interest from 2H26)
A30: Adjusted EBITDA (company definition of each era) and segment profit
A31: Adjusted EBITDA | B31: ='Segment History'!B13 | C31: ='Segment History'!C13 | D31: ='Segment History'!D13 | E31: ='Segment History'!E13 | F31: ='Segment History'!F13 | G31: ='Segment History'!G13 | H31: ='Segment History'!H13 | I31: ='Segment History'!I13 | K31: ='Segment P&L'!B100 | L31: ='Segment P&L'!C100 | M31: ='Segment P&L'!D100 | N31: 752.5 | P31: ='Segment P&L'!G100 | Q31: ='Segment P&L'!J100 | R31: IHS Adj. EBITDA (FY14–21); MBGL Adj. EBITDA (10 exclusions to Q1-26, 6 after); FY26E guide midpoint. FY22: n/a
A32: Adjusted EBITDA growth y/y | C32: =C31/B31-1 | D32: =D31/C31-1 | E32: =E31/D31-1 | F32: =F31/E31-1 | G32: =G31/F31-1 | H32: =H31/G31-1 | I32: =I31/H31-1 | L32: =L31/K31-1 | M32: =M31/L31-1 | N32: =N31/M31-1 | Q32: =Q31/P31-1 | R32: [C] within era only; FY2026E vs FY2025; 1H26 vs 1H25
A33: Adjusted EBITDA margin | B33: =IF(B7=0,"",B31/B7) | C33: =IF(C7=0,"",C31/C7) | D33: =IF(D7=0,"",D31/D7) | E33: =IF(E7=0,"",E31/E7) | F33: =IF(F7=0,"",F31/F7) | G33: =IF(G7=0,"",G31/G7) | H33: =IF(H7=0,"",H31/H7) | I33: =IF(I7=0,"",I31/I7) | K33: =IF(K7=0,"",K31/K7) | L33: =IF(L7=0,"",L31/L7) | M33: =IF(M7=0,"",M31/M7) | N33: =IF(N7=0,"",N31/N7) | P33: =IF(P7=0,"",P31/P7) | Q33: =IF(Q7=0,"",Q31/Q7) | R33: [C]
A34: Memo: operating profit + D&A (unadjusted) [C] | J34: ='Segment History'!J38 | K34: =K24+K21+K22 | L34: =L24+L21+L22 | M34: =M24+M21+M22 | P34: =P24+P21+P22 | Q34: =Q24+Q21+Q22 | R34: FY22 SPGI segment; FY23+ IS
A35: Segment Adj. EBITDA: CARFAX | K35: ='Segment P&L'!B25 | L35: ='Segment P&L'!C25 | M35: ='Segment P&L'!D25 | P35: ='Segment P&L'!G25 | Q35: ='Segment P&L'!J25 | R35: Segment P&L tab (company-reported)
A36: Segment Adj. EBITDA: B2B | K36: ='Segment P&L'!B54 | L36: ='Segment P&L'!C54 | M36: ='Segment P&L'!D54 | P36: ='Segment P&L'!G54 | Q36: ='Segment P&L'!J54 | R36: Segment P&L tab (company-reported)
A37: Segment Adj. EBITDA: Corporate | K37: ='Segment P&L'!B73 | L37: ='Segment P&L'!C73 | M37: ='Segment P&L'!D73 | P37: ='Segment P&L'!G73 | Q37: ='Segment P&L'!J73 | R37: Segment P&L tab (company-reported)
A38: CARFAX Adj. EBITDA margin | K38: =IF(K15=0,"",K35/K15) | L38: =IF(L15=0,"",L35/L15) | M38: =IF(M15=0,"",M35/M15) | P38: =IF(P15=0,"",P35/P15) | Q38: =IF(Q15=0,"",Q35/Q15) | R38: [C]
A39: B2B Adj. EBITDA margin | K39: =IF(K16=0,"",K36/K16) | L39: =IF(L16=0,"",L36/L16) | M39: =IF(M16=0,"",M36/M16) | P39: =IF(P16=0,"",P36/P16) | Q39: =IF(Q16=0,"",Q36/Q16) | R39: [C]
A40: Balance sheet (period-end). Segment assets only before FY2024
A41: Segment total assets (IHS Transportation / SPGI Mobility) | B41: ='Segment History'!B20 | C41: ='Segment History'!C20 | D41: ='Segment History'!D20 | E41: ='Segment History'!E20 | F41: ='Segment History'!F20 | G41: ='Segment History'!G20 | H41: ='Segment History'!H20 | I41: ='Segment History'!I20 | J41: ='Segment History'!J41 | K41: ='Segment History'!K41 | R41: IHS / SPGI segment notes. FY22 jump = S&P Global purchase accounting (goodwill/intangibles step-up), not growth
...

Sheet Cover & Basis
A1: Mobility Global Inc. (NYSE: MBGL) — Audit-quality historical financial model
A2: Built 2026-10-06 from primary filings via the Quartr connector. All figures as originally reported.
A4: Company | B4: Mobility Global Inc. (Delaware); spin-off of S&P Global Mobility (CARFAX, automotiveMastermind, Polk Automotive Solutions, Market Scan). Distribution 2026-07-01 (record date 2026-06-15), ratio 1:1; S&P Global retained no stake.
A5: Listing / ticker | B5: NYSE: MBGL
A6: Regulator ID | B6: SEC File No. 001-43276; IRS EIN 39-4621962. EDGAR CIK not confirmed (sec.gov blocked by sandbox network policy).
A7: GAAP / currency | B7: US GAAP; USD millions (per-share in USD). Fiscal year ends December 31.
A8: Basis of preparation | B8: Combined (carve-out) financial statements of the Mobility business of S&P Global — include allocations of S&P Global corporate costs; not necessarily indicative of standalone results. Standalone from distribution (Q3-2026 onward).
A9: Periods | B9: Income statement & cash flow FY2023–FY2025 (audited), Q1-2025/Q1-2026 (Form 10/A), Q2 and 6M 2025/2026 (10-Q). Balance sheets 12/31/24, 12/31/25, 3/31/26, 6/30/26. Predecessor segment history FY2014–FY2025 on its own tab.
A10: Sources | B10: Form 10-12B (2026-05-07), Form 10-12B/A (2026-05-27), 10-Q Q2-2026 (2026-08-07), 8-K earnings release (2026-08-07), Investor Day deck (2026-05-12), Q2-2026 deck; S&P Global 10-K FY2022–FY2025; IHS Markit 10-K FY2016–FY2021. All read via Quartr page text.
A11: Source limitation | B11: Native filings (EDGAR, Quartr PDF CDN, Wayback) were blocked by the sandbox network policy; Quartr page text flattens tables and corrupts some digits. Unreadable cells are left blank and logged (Accounting Notes, *_NOTES.md). No XBRL cross-check was possible — verification is cross-document (Form 10 vs 10/A vs 10-Q vs 8-K vs decks).
A12: Conventions | B12: Blank = not reported / not machine-readable; dash = reported zero. Blue = hard input as filed; black = in-sheet formula; green = cross-sheet formula. "0.0%" literal format = as-printed percentage; true % = computed ratio. Check rows marked CHECK (hidden col Z).
A13: Tiers | B13: [D] disclosed · [C] computed · [E] estimate · [IR] management verbal · [X] third party · [context] general knowledge.
A14: Tabs | B14: Annual Summary (front: FY14–FY26E P&L, balance sheet, cash flow, segments) · Accounting Notes · IS · BS · CF · Key Metrics · Segment P&L · Segments · Revenue Detail · Adjusted Non-GAAP · Operating KPIs · notes tabs (Debt, Tax, Equity, OCI, Pension, Goodwill & Intangibles, Related Party, Leases, Commitments, Deferred Revenue) · Pro Forma · Segment History · Predecessor Segments · Acquisitions · Presentation Data · Qualitative · Caption Map

Sheet Accounting Notes
A1: Accounting Notes — breaks, restatements, definition changes, non-disclosures, data-quality flags
A2: One row per item. Tier: [D] disclosed; [C] computed; flag types: BREAK / RESTATE / DEFN / NONDISC / DATAQ / BASIS.
A4: Type | B4: Area | C4: Item | D4: Source | E4: Model treatment
A5: BASIS | B5: All | C5: Carve-out (combined) statements of S&P Global Mobility; include S&P Global corporate allocations; not indicative of standalone costs. Standalone from distribution 2026-07-01. | D5: Form10A Basis of presentation; 10-Q Note 1 | E5: Shown as reported; standalone deltas tracked in analysis/D3
A6: RESTATE | B6: All statements | C6: Form 10 (2026-05-07) vs Form 10/A (2026-05-27): annual and Q1 statements identical — no quiet restatement found (text artefacts only). | D6: statements_NOTES.md | E6: None needed
A7: DEFN | B7: IS | C7: 10-Q retitles "Statements of Income" to "Statements of Operations"; captions condense (PP&E net of accumulated depreciation; Operating lease liabilities; Deferred tax liability, net). | D7: 10-Q pp.4-7 | E7: Mapped to same canonical rows (Caption Map)
A8: DATAQ | B8: IS / EPS | C8: 10-Q prints EPS for carve-out comparatives (Q2-25 $0.22; 6M-25 $0.42) though Form 10 states EPS "not presented" (no capital structure). Basis not stated (presumably ~295m shares). | D8: 10-Q p.4; Form10A F-pages | E8: Recorded as printed; flagged for D4 red-flags
A9: DATAQ | B9: IS | C9: "Other income, net" printed in the expense block: FY2024 (1), FY2023 (2) = income; FY2025 dash. | D9: Form10A p.440 | E9: Input as printed (negative = income); formula subtracts it
A10: DATAQ | B10: CF | C10: Annual CF "Restructuring and other" and nine working-capital lines (FY2023-25) unreadable in Quartr text (scrambled, values dropped; no unique arrangement fits CFO). | D10: Form10A p.443 | E10: Left blank; CFO component check = n/a; needs native PDF
A11: DATAQ | B11: CF | C11: Q1-2025/Q1-2026 working-capital lines and most Q1 financing components unreadable. | D11: Form10A p.425 | E11: Left blank; Q1-25 CFI/CFF from MD&A cash-flow overview p.361 (logged fallback)
A12: DATAQ | B12: CF | C12: FY2024 cash used for investing unreadable in statement; (21) from MD&A overview p.361 and Summary p.285 (= capex 15 + acquisitions 6). | D12: Form10A p.361 | E12: Logged fallback in canonical/primary_merge_log.txt
A13: DATAQ | B13: CF | C13: Annual contingent consideration legible only FY2024 (5); FY2025/FY2023 implied (2) each by CFF tie — NOT recorded. | D13: Form10A p.443 | E13: Blank
A14: NONDISC | B14: CF | C14: No standalone Q2 cash-flow statement (6M only); no 3/31/25 or 6/30/25 balance sheets; no FY2023 balance sheet. | D14: 10-Q; Form10A | E14: Blank
A15: DEFN | B15: CF | C15: 8-K titles CF "Consolidated" (10-Q "Combined") and collapses working capital into one line (46)/(13). | D15: 8-K p.7 | E15: 8-K used only as cross-check
... A45: NONDISC | B45: Segment P&L | C45: Operating-related vs selling & general expense split by segment is printed for FY2023–25 and Q1 (Form 10/A) but not for Q2/6M (10-Q). | D45: 10-Q Note 7 | E45: Memo rows blank for Q2/6M

Sheet IS
A1: Mobility Global Inc. — Combined Statements of Income (as originally reported)
A2: Carve-out (combined) basis; FY from Form 10/A (2026-05-27) audited statements; Q1 from Form 10/A interim; Q2/6M from 10-Q Q2-2026. Blue = as filed; black = formula; green = cross-sheet.
A4: USD millions unless stated | B4: FY2023 12/31/23 | C4: FY2024 12/31/24 | D4: FY2025 12/31/25 | E4: Q1-25 3M 3/31/25 | F4: Q2-25 3M 6/30/25 | G4: 6M-25 6/30/25 | H4: Q1-26 3M 3/31/26 | I4: Q2-26 3M 6/30/26 | J4: 6M-26 6/30/26 | K4: Source
A5: Income statement
A6: Revenue | B6: 1485 | C6: 1613 | D6: 1750 | E6: 420 | F6: 439 | G6: 859 | H6: 455 | I6: 468 | J6: 923 | K6: 10Q_Q2-2026 p4; Form10A_2026-05-27 p422; Form10A_2026-05-27 p440
A7: Operating-related expenses | B7: 448 | C7: 475 | D7: 516 | E7: 127 | F7: 132 | G7: 259 | H7: 136 | I7: 134 | J7: 270 | K7: 10Q_Q2-2026 p4; Form10A_2026-05-27 p422; Form10A_2026-05-27 p440
A8: Selling and general expenses | B8: 491 | C8: 531 | D8: 585 | E8: 131 | F8: 134 | G8: 265 | H8: 160 | I8: 175 | J8: 335 | K8: 10Q_Q2-2026 p4; Form10A_2026-05-27 p422; Form10A_2026-05-27 p440
A9: Depreciation | B9: 12 | C9: 13 | D9: 14 | E9: 4 | F9: 3 | G9: 7 | H9: 4 | I9: 3 | J9: 7 | K9: 10Q_Q2-2026 p4; Form10A_2026-05-27 p422; Form10A_2026-05-27 p440
A10: Amortization of intangibles | B10: 295 | C10: 296 | D10: 296 | E10: 74 | F10: 74 | G10: 148 | H10: 74 | I10: 74 | J10: 148 | K10: 10Q_Q2-2026 p4; Form10A_2026-05-27 p422; Form10A_2026-05-27 p440
A11: Total expenses | B11: =B7+B8+B9+B10 | C11: =C7+C8+C9+C10 | D11: =D7+D8+D9+D10 | E11: =E7+E8+E9+E10 | F11: =F7+F8+F9+F10 | G11: =G7+G8+G9+G10 | H11: =H7+H8+H9+H10 | I11: =I7+I8+I9+I10 | J11: =J7+J8+J9+J10
A12: Operating profit | B12: =B6-B11 | C12: =C6-C11 | D12: =D6-D11 | E12: =E6-E11 | F12: =F6-F11 | G12: =G6-G11 | H12: =H6-H11 | I12: =I6-I11 | J12: =J6-J11
A13: Other income, net (printed as a deduction; negative = income) | B13: -2 | C13: -1 | K13: Form10A_2026-05-27 p440
A14: Interest expense, net | B14: 17 | C14: 15 | D14: 13 | E14: 3 | F14: 4 | G14: 7 | H14: 3 | I14: 7 | J14: 10 | K14: 10Q_Q2-2026 p4; Form10A_2026-05-27 p422; Form10A_2026-05-27 p440
A15: Income before taxes on income | B15: =B12-B13-B14 | C15: =C12-C13-C14 | D15: =D12-D13-D14 | E15: =E12-E13-E14 | F15: =F12-F13-F14 | G15: =G12-G13-G14 | H15: =H12-H13-H14 | I15: =I12-I13-I14 | J15: =J12-J13-J14
A16: Provision for taxes on income | B16: 61 | C16: 76 | D16: 106 | E16: 23 | F16: 27 | G16: 50 | H16: 23 | I16: 22 | J16: 45 | K16: 10Q_Q2-2026 p4; Form10A_2026-05-27 p422; Form10A_2026-05-27 p440
A17: Net income | B17: =B15-B16 | C17: =C15-C16 | D17: =D15-D16 | E17: =E15-E16 | F17: =F15-F16 | G17: =G15-G16 | H17: =H15-H16 | I17: =I15-I16 | J17: =J15-J16
A18: Net income per common share — basic (10-Q only; Form 10 says EPS not presented) | F18: 0.22 | G18: 0.42 | I18: 0.18 | J18: 0.37 | K18: 10Q_Q2-2026 p4
A19: Net income per common share — diluted (10-Q only) | F19: 0.22 | G19: 0.42 | I19: 0.18 | J19: 0.37 | K19: 10Q_Q2-2026 p4
A20: Comprehensive income
A21: Foreign currency translation adjustments | B21: -6 | C21: 18 | D21: -7 | E21: -1 | F21: -7 | G21: -8 | H21: 1 | I21: 5 | J21: 6 | K21: 10Q_Q2-2026 p5; Form10A_2026-05-27 p423; Form10A_2026-05-27 p441
A22: Comprehensive income | B22: =B17+B21 | C22: =C17+C21 | D22: =D17+D21 | E22: =E17+E21 | F22: =F17+F21 | G22: =G17+G21 | H22: =H17+H21 | I22: =I17+I21 | J22: =J17+J21
A23: Printed subtotals (as filed — for integrity checks)
A24: Total expenses — printed | B24: 1246 | C24: 1315 | D24: 1411 | E24: 336 | F24: 343 | G24: 679 | H24: 374 | I24: 386 | J24: 760 | K24: 10Q_Q2-2026 p4; Form10A_2026-05-27 p422; Form10A_2026-05-27 p440
A25: Operating profit — printed | B25: 239 | C25: 298 | D25: 339 | E25: 84 | F25: 96 | G25: 180 | H25: 81 | I25: 82 | J25: 163 | K25: 10Q_Q2-2026 p4; Form10A_2026-05-27 p422; Form10A_2026-05-27 p440
A26: Income before taxes — printed | B26: 224 | C26: 284 | D26: 326 | E26: 81 | F26: 92 | G26: 173 | H26: 78 | I26: 75 | J26: 153 | K26: 10Q_Q2-2026 p4; Form10A_2026-05-27 p422; Form10A_2026-05-27 p440
A27: Net income — printed | B27: 163 | C27: 208 | D27: 220 | E27: 58 | F27: 65 | G27: 123 | H27: 55 | I27: 53 | J27: 108 | K27: 10Q_Q2-2026 p4; Form10A_2026-05-27 p422; Form10A_2026-05-27 p440
A28: Comprehensive income — printed | B28: 157 | C28: 226 | D28: 213 | E28: 57 | F28: 58 | G28: 115 | H28: 56 | I28: 58 | J28: 114 | K28: 10Q_Q2-2026 p5; Form10A_2026-05-27 p423; Form10A_2026-05-27 p441
A29: Integrity checks (formula − printed; must be 0)
A30: CHECK total expenses | B30: =B11-B24 | C30: =C11-C24 | D30: =D11-D24 | E30: =E11-E24 | F30: =F11-F24 | G30: =G11-G24 | H30: =H11-H24 | I30: =I11-I24 | J30: =J11-J24 | Z30: CHECK
A31: CHECK operating profit | B31: =B12-B25 | C31: =C12-C25 | D31: =D12-D25 | E31: =E12-E25 | F31: =F12-F25 | G31: =G12-G25 | H31: =H12-H25 | I31: =I12-I25 | J31: =J12-J25 | Z31: CHECK
A32: CHECK pre-tax income | B32: =B15-B26 | C32: =C15-C26 | D32: =D15-D26 | E32: =E15-E26 | F32: =F15-F26 | G32: =G15-G26 | H32: =H15-H26 | I32: =I15-I26 | J32: =J15-J26 | Z32: CHECK
A33: CHECK net income | B33: =B17-B27 | C33: =C17-C27 | D33: =D17-D27 | E33: =E17-E27 | F33: =F17-F27 | G33: =G17-G27 | H33: =H17-H27 | I33: =I17-I27 | J33: =J17-J27 | Z33: CHECK
A34: CHECK comprehensive income | B34: =B22-B28 | C34: =C22-C28 | D34: =D22-D28 | E34: =E22-E28 | F34: =F22-F28 | G34: =G22-G28 | H34: =H22-H28 | I34: =I22-I28 | J34: =J22-J28 | Z34: CHECK
A35: CHECK 6M = Q1 + Q2 (revenue and net income) | B35: n/a | C35: n/a | D35: n/a | E35: n/a | F35: n/a | G35: =ABS(G6-E6-F6)+ABS(G17-E17-F17) | H35: n/a | I35: n/a | J35: =ABS(J6-H6-I6)+ABS(J17-H17-I17) | Z35: CHECK
A37: Notes: Form 10 (2026-05-07) and Form 10/A statements are identical (no quiet restatement). The 10-Q prints EPS for carve-out comparatives although the Form 10 states EPS was not presented (no capital structure) — see Accounting Notes.

Sheet BS
A1: Mobility Global Inc. — Combined Balance Sheets (as originally reported)
A2: 12/31/24 & 12/31/25 from Form 10/A audited; 3/31/26 Form 10/A interim; 6/30/26 10-Q. No FY2023 balance sheet is printed.
A4: USD millions unless stated | B4: 12/31/24 | C4: 12/31/25 | D4: 3/31/26 | E4: 6/30/26 | F4: Source
A5: Assets
A6: Cash and cash equivalents | B6: 27 | C6: 38 | D6: 122 | E6: 186 | F6: 10Q_Q2-2026 p6; Form10A_2026-05-27 p424; Form10A_2026-05-27 p442
A7: Due from related parties — current | B7: 4 | C7: 8 | D7: 15 | E7: 17 | F7: 10Q_Q2-2026 p6; Form10A_2026-05-27 p424; Form10A_2026-05-27 p442
A8: Accounts receivable, net | B8: 195 | C8: 203 | D8: 216 | E8: 216 | F8: 10Q_Q2-2026 p6; Form10A_2026-05-27 p424; Form10A_2026-05-27 p442
A9: Prepaid and other current assets | B9: 24 | C9: 32 | D9: 39 | E9: 47 | F9: 10Q_Q2-2026 p6; Form10A_2026-05-27 p424; Form10A_2026-05-27 p442
A10: Total current assets | B10: =B6+B7+B8+B9 | C10: =C6+C7+C8+C9 | D10: =D6+D7+D8+D9 | E10: =E6+E7+E8+E9
A11: Total property and equipment (gross) | B11: 103 | C11: 100 | D11: 102 | F11: Form10A_2026-05-27 p424; Form10A_2026-05-27 p442
A12: Less: accumulated depreciation | B12: -83 | C12: -81 | D12: -83 | F12: Form10A_2026-05-27 p424; Form10A_2026-05-27 p442
A13: Property and equipment, net | B13: 20 | C13: 19 | D13: 19 | E13: 18 | F13: 10Q_Q2-2026 p6; Form10A_2026-05-27 p424; Form10A_2026-05-27 p442
A14: Right of use assets | B14: 20 | C14: 16 | D14: 23 | E14: 33 | F14: 10Q_Q2-2026 p6; Form10A_2026-05-27 p424; Form10A_2026-05-27 p442
A15: Goodwill | B15: 8845 | C15: 8845 | D15: 8845 | E15: 8845 | F15: 10Q_Q2-2026 p6; Form10A_2026-05-27 p424; Form10A_2026-05-27 p442
A16: Other intangible assets, net | B16: 4085 | C16: 3789 | D16: 3714 | E16: 3640 | F16: 10Q_Q2-2026 p6; Form10A_2026-05-27 p424; Form10A_2026-05-27 p442
A17: Due from related parties — non-current | B17: 4 | F17: Form10A_2026-05-27 p442
A18: Other non-current assets | B18: 31 | C18: 45 | D18: 49 | E18: 58 | F18: 10Q_Q2-2026 p6; Form10A_2026-05-27 p424; Form10A_2026-05-27 p442
A19: Total assets | B19: =B10+B13+B14+B15+B16+B17+B18 | C19: =C10+C13+C14+C15+C16+C17+C18 | D19: =D10+D13+D14+D15+D16+D17+D18 | E19: =E10+E13+E14+E15+E16+E17+E18
A20: Liabilities and equity
A21: Accounts payable | B21: 38 | C21: 56 | D21: 48 | E21: 63 | F21: 10Q_Q2-2026 p6; Form10A_2026-05-27 p424; Form10A_2026-05-27 p442
A22: Due to related parties — current | B22: 12 | C22: 19 | D22: 24 | F22: Form10A_2026-05-27 p424; Form10A_2026-05-27 p442
A23: Accrued compensation and contributions to retirement plans | B23: 56 | C23: 64 | D23: 25 | E23: 41 | F23: 10Q_Q2-2026 p6; Form10A_2026-05-27 p424; Form10A_2026-05-27 p442
A24: Unearned revenue | B24: 75 | C24: 78 | D24: 94 | E24: 102 | F24: 10Q_Q2-2026 p6; Form10A_2026-05-27 p424; Form10A_2026-05-27 p442
A25: Other current liabilities | B25: 40 | C25: 45 | D25: 38 | E25: 42 | F25: 10Q_Q2-2026 p6; Form10A_2026-05-27 p424; Form10A_2026-05-27 p442
A26: Total current liabilities | B26: =B21+B22+B23+B24+B25 | C26: =C21+C22+C23+C24+C25 | D26: =D21+D22+D23+D24+D25 | E26: =E21+E22+E23+E24+E25
A27: Long-term debt (Senior Notes, from 6/30/26) | E27: 1981 | F27: 10Q_Q2-2026 p6
A28: Lease liabilities — non-current (10-Q: "Operating lease liabilities") | B28: 16 | C28: 11 | D28: 19 | E28: 27 | F28: 10Q_Q2-2026 p6; Form10A_2026-05-27 p424; Form10A_2026-05-27 p442
A29: Deferred tax liability — non-current | B29: 1096 | C29: 1006 | D29: 983 | E29: 967 | F29: 10Q_Q2-2026 p6; Form10A_2026-05-27 p424; Form10A_2026-05-27 p442
A30: Due to related parties — non-current (Canada Carfax loan) | B30: 236 | C30: 230 | D30: 227 | F30: Form10A_2026-05-27 p424; Form10A_2026-05-27 p442
A31: Other non-current liabilities | B31: 3 | C31: 1 | D31: 1 | E31: 2 | F31: 10Q_Q2-2026 p6; Form10A_2026-05-27 p424; Form10A_2026-05-27 p442
A32: Total liabilities | B32: =B26+B27+B28+B29+B30+B31 | C32: =C26+C27+C28+C29+C30+C31 | D32: =D26+D27+D28+D29+D30+D31 | E32: =E26+E27+E28+E29+E30+E31
A33: Parent company investment | B33: 11680 | C33: 11489 | D33: 11586 | E33: 9833 | F33: 10Q_Q2-2026 p6; Form10A_2026-05-27 p424; Form10A_2026-05-27 p442
A34: Accumulated other comprehensive income (loss) | B34: 3 | C34: -4 | D34: -3 | E34: 2 | F34: 10Q_Q2-2026 p6; Form10A_2026-05-27 p424; Form10A_2026-05-27 p442
A35: Total equity | B35: =B33+B34 | C35: =C33+C34 | D35: =D33+D34 | E35: =E33+E34
A36: Total liabilities and equity | B36: =B32+B35 | C36: =C32+C35 | D36: =D32+D35 | E36: =E32+E35
A37: Printed subtotals (as filed)
A38: Total current assets — printed | B38: 250 | C38: 281 | D38: 392 | E38: 466 | F38: 10Q_Q2-2026 p6; Form10A_2026-05-27 p424; Form10A_2026-05-27 p442
A39: Total assets — printed | B39: 13255 | C39: 12995 | D39: 13042 | E39: 13060 | F39: 10Q_Q2-2026 p6; Form10A_2026-05-27 p424; Form10A_2026-05-27 p442
A40: Total current liabilities — printed | B40: 221 | C40: 262 | D40: 229 | E40: 248 | F40: 10Q_Q2-2026 p6; Form10A_2026-05-27 p424; Form10A_2026-05-27 p442
A41: Total liabilities — printed | B41: 1572 | C41: 1510 | D41: 1459 | E41: 3225 | F41: 10Q_Q2-2026 p6; Form10A_2026-05-27 p424; Form10A_2026-05-27 p442
...

Sheet CF
A1: Mobility Global Inc. — Combined Statements of Cash Flows (as originally reported)
A2: Annual "Restructuring and other" and working-capital lines (Form 10/A p.443) and Q1 working-capital lines are NOT machine-readable in the Quartr text — left blank, never derived. No standalone Q2 cash flow is printed.
A4: USD millions unless stated | B4: FY2023 12/31/23 | C4: FY2024 12/31/24 | D4: FY2025 12/31/25 | E4: Q1-25 3M 3/31/25 | F4: Q2-25 3M 6/30/25 | G4: 6M-25 6/30/25 | H4: Q1-26 3M 3/31/26 | I4: Q2-26 3M 6/30/26 | J4: 6M-26 6/30/26 | K4: Source
A5: Operating activities
A6: Net income | B6: 163 | C6: 208 | D6: 220 | E6: 58 | G6: 123 | H6: 55 | J6: 108 | K6: 10Q_Q2-2026 p7; Form10A_2026-05-27 p425; Form10A_2026-05-27 p443
A7: Depreciation | B7: 12 | C7: 13 | D7: 14 | E7: 4 | G7: 7 | H7: 4 | J7: 7 | K7: 10Q_Q2-2026 p7; Form10A_2026-05-27 p425; Form10A_2026-05-27 p443
A8: Amortization of intangibles | B8: 295 | C8: 296 | D8: 296 | E8: 74 | G8: 148 | H8: 74 | J8: 148 | K8: 10Q_Q2-2026 p7; Form10A_2026-05-27 p425; Form10A_2026-05-27 p443
A9: Provision for losses on accounts receivable | B9: 4 | C9: 4 | D9: 4 | E9: 1 | G9: 2 | H9: 1 | J9: 2 | K9: 10Q_Q2-2026 p7; Form10A_2026-05-27 p425; Form10A_2026-05-27 p443
A10: Deferred income taxes | B10: -95 | C10: -102 | D10: -90 | E10: -23 | G10: -43 | H10: -23 | J10: -38 | K10: 10Q_Q2-2026 p7; Form10A_2026-05-27 p425; Form10A_2026-05-27 p443
A11: Stock-based compensation | B11: 20 | C11: 28 | D11: 22 | E11: 5 | G11: 9 | H11: 4 | J11: 9 | K11: 10Q_Q2-2026 p7; Form10A_2026-05-27 p425; Form10A_2026-05-27 p443
A12: Restructuring and other
A13: Other | J13: -1 | K13: 10Q_Q2-2026 p7
A14: Δ Accounts receivable | G14: -4 | J14: -16 | K14: 10Q_Q2-2026 p7
A15: Δ Due from related parties | G15: 2 | J15: -8 | K15: 10Q_Q2-2026 p7
A16: Δ Prepaid and other current assets | G16: -4 | J16: -15 | K16: 10Q_Q2-2026 p7
A17: Δ Accounts payable and accrued expenses | G17: -25 | J17: -26 | K17: 10Q_Q2-2026 p7
A18: Δ Due to related parties | G18: 12 | J18: -19 | K18: 10Q_Q2-2026 p7
A19: Δ Unearned revenue | G19: 20 | J19: 25 | K19: 10Q_Q2-2026 p7
A20: Δ Other current liabilities | J20: 11 | K20: 10Q_Q2-2026 p7
A21: Net change in other assets and liabilities | G21: -14 | J21: 2 | K21: 10Q_Q2-2026 p7
A22: Cash provided by operating activities | B22: 393 | C22: 427 | D22: 485 | E22: 67 | G22: 233 | H22: 54 | J22: 189 | K22: 10Q_Q2-2026 p7; Form10A_2026-05-27 p425; Form10A_2026-05-27 p443
A23: Investing activities
A24: Capital expenditures | B24: -18 | C24: -15 | D24: -24 | G24: -8 | H24: -6 | J24: -12 | K24: 10Q_Q2-2026 p7; Form10A_2026-05-27 p425; Form10A_2026-05-27 p443
A25: Acquisitions, net of cash acquired | B25: -214 | C25: -6 | D25: -4 | K25: Form10A_2026-05-27 p443
A26: Proceeds from loan to related parties | D26: 5 | K26: Form10A_2026-05-27 p443
A27: Proceeds from dispositions | B27: 2 | K27: Form10A_2026-05-27 p443
A28: Purchases of equity investments | G28: -3 | J28: -3 | K28: 10Q_Q2-2026 p7
A29: Cash used for investing activities (FY2024 & Q1-25 from MD&A cash-flow overview — statement cell unreadable) | B29: -230 | C29: -21 | D29: -23 | E29: -5 | G29: -11 | H29: -6 | J29: -15 | K29: 10Q_Q2-2026 p7; Form10A_2026-05-27 p361; Form10A_2026-05-27 p425; Form10A_2026-05-27 p443
A30: Financing activities
A31: Proceeds from issuance of Senior Notes | J31: 1986 | K31: 10Q_Q2-2026 p7
A32: Net transfers to Parent | B32: -158 | C32: -373 | D32: -433 | G32: -190 | J32: -2011 | K32: 10Q_Q2-2026 p7; Form10A_2026-05-27 p443
A33: Payments related to loan from related parties | C33: -45 | D33: -18 | G33: -18 | K33: 10Q_Q2-2026 p7; Form10A_2026-05-27 p443
A34: Contingent consideration payments | C34: -5 | G34: -2 | K34: 10Q_Q2-2026 p7; Form10A_2026-05-27 p443
A35: Cash provided by (used for) financing activities (Q1-25 from MD&A) | B35: -160 | C35: -423 | D35: -453 | E35: -62 | G35: -210 | H35: 37 | J35: -25 | K35: 10Q_Q2-2026 p7; Form10A_2026-05-27 p361; Form10A_2026-05-27 p425; Form10A_2026-05-27 p443
A36: Effect of exchange rate changes on cash | B36: 2 | C36: -3 | D36: 2 | G36: 1 | H36: -1 | J36: -1 | K36: 10Q_Q2-2026 p7; Form10A_2026-05-27 p425; Form10A_2026-05-27 p443
A37: Net change in cash, cash equivalents and restricted cash | B37: 5 | C37: -20 | D37: 11 | E37: 1 | G37: 13 | H37: 84 | J37: 148 | K37: 10Q_Q2-2026 p7; Form10A_2026-05-27 p425; Form10A_2026-05-27 p443
A38: Cash at beginning of period | B38: 42 | C38: 47 | D38: 27 | E38: 27 | G38: 27 | H38: 38 | J38: 38 | K38: 10Q_Q2-2026 p7; Form10A_2026-05-27 p425; Form10A_2026-05-27 p443
A39: Cash at end of period | B39: 47 | C39: 27 | D39: 38 | E39: 28 | G39: 40 | H39: 122 | J39: 186 | K39: 10Q_Q2-2026 p7; Form10A_2026-05-27 p425; Form10A_2026-05-27 p443
A40: Supplemental
A41: Cash paid for interest | B41: 18 | C41: 17 | D41: 14 | K41: Form10A_2026-05-27 p443
...

Sheet Key Metrics
A1: Key Metrics — computed [C] from IS / BS / CF (formulas only)
A2: Growth only between comparable periods (same length, prior year). FY2023 growth suppressed: no FY2022 carve-out statements printed. No 53-week years (calendar Dec-31 FYE).
A4: Ratio / metric | B4: FY2023 12/31/23 | C4: FY2024 12/31/24 | D4: FY2025 12/31/25 | E4: Q1-25 3M 3/31/25 | F4: Q2-25 3M 6/30/25 | G4: 6M-25 6/30/25 | H4: Q1-26 3M 3/31/26 | I4: Q2-26 3M 6/30/26 | J4: 6M-26 6/30/26 | K4: Definition
A5: Growth, margins, cash conversion
A6: Revenue growth (y/y) | C6: ='IS'!C6/'IS'!B6-1 | D6: ='IS'!D6/'IS'!C6-1 | H6: ='IS'!H6/'IS'!E6-1 | I6: ='IS'!I6/'IS'!F6-1 | J6: ='IS'!J6/'IS'!G6-1 | K6: Revenue / prior-year comparable period − 1
A7: Operating-related expenses % revenue | B7: ='IS'!B7/'IS'!B6 | C7: ='IS'!C7/'IS'!C6 | D7: ='IS'!D7/'IS'!D6 | E7: ='IS'!E7/'IS'!E6 | F7: ='IS'!F7/'IS'!F6 | G7: ='IS'!G7/'IS'!G6 | H7: ='IS'!H7/'IS'!H6 | I7: ='IS'!I7/'IS'!I6 | J7: ='IS'!J7/'IS'!J6
A8: Selling & general % revenue | B8: ='IS'!B8/'IS'!B6 | C8: ='IS'!C8/'IS'!C6 | D8: ='IS'!D8/'IS'!D6 | E8: ='IS'!E8/'IS'!E6 | F8: ='IS'!F8/'IS'!F6 | G8: ='IS'!G8/'IS'!G6 | H8: ='IS'!H8/'IS'!H6 | I8: ='IS'!I8/'IS'!I6 | J8: ='IS'!J8/'IS'!J6
A9: EBITDA (operating profit + D&A) [C] | B9: ='IS'!B12+'IS'!B9+'IS'!B10 | C9: ='IS'!C12+'IS'!C9+'IS'!C10 | D9: ='IS'!D12+'IS'!D9+'IS'!D10 | E9: ='IS'!E12+'IS'!E9+'IS'!E10 | F9: ='IS'!F12+'IS'!F9+'IS'!F10 | G9: ='IS'!G12+'IS'!G9+'IS'!G10 | H9: ='IS'!H12+'IS'!H9+'IS'!H10 | I9: ='IS'!I12+'IS'!I9+'IS'!I10 | J9: ='IS'!J12+'IS'!J9+'IS'!J10 | K9: Unadjusted; company Adjusted EBITDA is on the Non-GAAP tab
A10: EBITDA margin [C] | B10: =(B9)/'IS'!B6 | C10: =(C9)/'IS'!C6 | D10: =(D9)/'IS'!D6 | E10: =(E9)/'IS'!E6 | F10: =(F9)/'IS'!F6 | G10: =(G9)/'IS'!G6 | H10: =(H9)/'IS'!H6 | I10: =(I9)/'IS'!I6 | J10: =(J9)/'IS'!J6
A11: Operating margin | B11: ='IS'!B12/'IS'!B6 | C11: ='IS'!C12/'IS'!C6 | D11: ='IS'!D12/'IS'!D6 | E11: ='IS'!E12/'IS'!E6 | F11: ='IS'!F12/'IS'!F6 | G11: ='IS'!G12/'IS'!G6 | H11: ='IS'!H12/'IS'!H6 | I11: ='IS'!I12/'IS'!I6 | J11: ='IS'!J12/'IS'!J6
A12: Amortization of intangibles % revenue | B12: ='IS'!B10/'IS'!B6 | C12: ='IS'!C10/'IS'!C6 | D12: ='IS'!D10/'IS'!D6 | E12: ='IS'!E10/'IS'!E6 | F12: ='IS'!F10/'IS'!F6 | G12: ='IS'!G10/'IS'!G6 | H12: ='IS'!H10/'IS'!H6 | I12: ='IS'!I10/'IS'!I6 | J12: ='IS'!J10/'IS'!J6 | K12: Acquisition (IHS Markit merger) step-up amortization
A13: Net margin | B13: ='IS'!B17/'IS'!B6 | C13: ='IS'!C17/'IS'!C6 | D13: ='IS'!D17/'IS'!D6 | E13: ='IS'!E17/'IS'!E6 | F13: ='IS'!F17/'IS'!F6 | G13: ='IS'!G17/'IS'!G6 | H13: ='IS'!H17/'IS'!H6 | I13: ='IS'!I17/'IS'!I6 | J13: ='IS'!J17/'IS'!J6
A14: Effective tax rate | B14: ='IS'!B16/'IS'!B15 | C14: ='IS'!C16/'IS'!C15 | D14: ='IS'!D16/'IS'!D15 | E14: ='IS'!E16/'IS'!E15 | F14: ='IS'!F16/'IS'!F15 | G14: ='IS'!G16/'IS'!G15 | H14: ='IS'!H16/'IS'!H15 | I14: ='IS'!I16/'IS'!I15 | J14: ='IS'!J16/'IS'!J15
A15: Free cash flow (CFO + capex) [C] | B15: ='CF'!B22+'CF'!B24 | C15: ='CF'!C22+'CF'!C24 | D15: ='CF'!D22+'CF'!D24 | G15: ='CF'!G22+'CF'!G24 | H15: ='CF'!H22+'CF'!H24 | J15: ='CF'!J22+'CF'!J24 | K15: Suppressed where capex not printed in the statement
A16: FCF / net income | B16: =B15/'IS'!B17 | C16: =C15/'IS'!C17 | D16: =D15/'IS'!D17 | G16: =G15/'IS'!G17 | H16: =H15/'IS'!H17 | J16: =J15/'IS'!J17
A17: FCF / (net income + amortization) [C] | B17: =B15/('IS'!B17+'IS'!B10) | C17: =C15/('IS'!C17+'IS'!C10) | D17: =D15/('IS'!D17+'IS'!D10) | G17: =G15/('IS'!G17+'IS'!G10) | H17: =H15/('IS'!H17+'IS'!H10) | J17: =J15/('IS'!J17+'IS'!J10) | K17: Cash conversion ex-acquired-intangible amortization (pre-tax amortization; indicative)
A18: Capex % revenue | B18: =-'CF'!B24/'IS'!B6 | C18: =-'CF'!C24/'IS'!C6 | D18: =-'CF'!D24/'IS'!D6 | G18: =-'CF'!G24/'IS'!G6 | H18: =-'CF'!H24/'IS'!H6 | J18: =-'CF'!J24/'IS'!J6
A19: Stock-based compensation % revenue | B19: ='CF'!B11/'IS'!B6 | C19: ='CF'!C11/'IS'!C6 | D19: ='CF'!D11/'IS'!D6 | E19: ='CF'!E11/'IS'!E6 | G19: ='CF'!G11/'IS'!G6 | H19: ='CF'!H11/'IS'!H6 | J19: ='CF'!J11/'IS'!J6 | K19: Carve-out SBC; mgmt guides 3–4% standalone [IR]
A20: Net transfers to Parent % CFO | B20: =-'CF'!B32/'CF'!B22 | C20: =-'CF'!C32/'CF'!C22 | D20: =-'CF'!D32/'CF'!D22 | G20: =-'CF'!G32/'CF'!G22 | J20: =-'CF'!J32/'CF'!J22

Sheet Segment P&L
A1: Segment P&L — uniform layout, CARFAX / B2B / Corporate (carve-out, as originally reported)
A2: Same rows in every period. Uniform Adjusted EBITDA = segment operating profit + amortization + depreciation + SBC + special items (all printed). FY & Q1: Form 10/A; Q2 & 6M: 10-Q. Company Adj. EBITDA definition changed (10 → 6 exclusions) at Q2-2026; the uniform build re-expresses every period on one basis. Blue = as filed; black = formula; green = cross-sheet.
A4: USD millions unless stated | B4: FY2023 12/31/23 | C4: FY2024 12/31/24 | D4: FY2025 12/31/25 | E4: Q1-25 3M 3/31/25 | F4: Q2-25 3M 6/30/25 | G4: 6M-25 6/30/25 | H4: Q1-26 3M 3/31/26 | I4: Q2-26 3M 6/30/26 | J4: 6M-26 6/30/26 | K4: Source / note
A5: CARFAX segment
A6: Revenue [D] | B6: 928 | C6: 1039 | D6: 1142 | E6: 275 | F6: 289 | G6: 564 | H6: 298 | I6: 312 | J6: 610 | K6: 10Q_Q2-2026; Form10A_2026-05-27
A7: Revenue growth y/y [C] | C7: =C6/B6-1 | D7: =D6/C6-1 | H7: =H6/E6-1 | I7: =I6/F6-1 | J7: =J6/G6-1 | K7: [C]
A8: Subscription [D] | B8: 748 | C8: 843 | D8: 927 | E8: 225 | F8: 234 | G8: 459 | H8: 242 | I8: 252 | J8: 494 | K8: 10Q_Q2-2026; Form10A_2026-05-27
A9: Non-subscription [D] | B9: 180 | C9: 196 | D9: 215 | E9: 50 | F9: 55 | G9: 105 | H9: 56 | I9: 60 | J9: 116 | K9: 10Q_Q2-2026; Form10A_2026-05-27
A10: Subscription share [C] | B10: =B8/B6 | C10: =C8/C6 | D10: =D8/D6 | E10: =E8/E6 | F10: =F8/F6 | G10: =G8/G6 | H10: =H8/H6 | I10: =I8/I6 | J10: =J8/J6 | K10: [C]
A11: U.S. [D] | B11: 791 | C11: 884 | D11: 974 | E11: 236 | F11: 246 | G11: 482 | H11: 253 | I11: 265 | J11: 518 | K11: 10Q_Q2-2026; Form10A_2026-05-27
A12: International [D] | B12: 137 | C12: 155 | D12: 168 | E12: 39 | F12: 43 | G12: 82 | H12: 45 | I12: 47 | J12: 92 | K12: 10Q_Q2-2026; Form10A_2026-05-27
A13: International growth y/y [C] | C13: =C12/B12-1 | D13: =D12/C12-1 | H13: =H12/E12-1 | I13: =I12/F12-1 | J13: =J12/G12-1 | K13: [C]
A14: Memo: operating-related expenses (FY & Q1 only — not split in 10-Q) [D] | B14: 221 | C14: 243 | D14: 258 | E14: 63 | H14: 68 | K14: Form10A_2026-05-27
A15: Memo: selling & general expenses (FY & Q1 only) [D] | B15: 300 | C15: 339 | D15: 363 | E15: 85 | H15: 91 | K15: Form10A_2026-05-27
A16: Segment operating profit (GAAP) [D] | B16: 210 | C16: 259 | D16: 322 | E16: 77 | F16: 89 | G16: 166 | H16: 89 | I16: 101 | J16: 190 | K16: 10Q_Q2-2026; Form10A_2026-05-27
A17: Operating margin [C] | B17: =B16/B6 | C17: =C16/C6 | D17: =D16/D6 | E17: =E16/E6 | F17: =F16/F6 | G17: =G16/G6 | H17: =H16/H6 | I17: =I16/I6 | J17: =J16/J6 | K17: [C]
A18: + Amortization of acquired intangibles [D] | B18: 190 | C18: 190 | D18: 189 | E18: 47 | F18: 48 | G18: 95 | H18: 47 | I18: 48 | J18: 95 | K18: 10Q_Q2-2026; Form10A_2026-05-27
A19: + Depreciation [D] | B19: 8 | C19: 9 | D19: 9 | E19: 3 | F19: 2 | G19: 5 | H19: 3 | I19: 2 | J19: 5 | K19: 10Q_Q2-2026; Form10A_2026-05-27
A20: + Stock-based compensation [D] | B20: 14 | C20: 18 | D20: 13 | E20: 3 | F20: 2 | G20: 5 | H20: 1 | I20: 2 | J20: 3 | K20: 10Q_Q2-2026; Form10A_2026-05-27
A21: + Transaction (separation) costs [D] | F21: 0 | G21: 0 | I21: 0 | J21: 0 | K21: 10Q_Q2-2026
A22: + Employee severance & other [D] | D22: 2 | F22: 1 | G22: 1 | I22: 0 | J22: 0 | K22: 10Q_Q2-2026; Form10A_2026-05-27
A23: + Acquisition / integration / legal recovery / ELT [D]
A24: Adjusted EBITDA — uniform build [C] | B24: =B16+B18+B19+B20+B21+B22+B23 | C24: =C16+C18+C19+C20+C21+C22+C23 | D24: =D16+D18+D19+D20+D21+D22+D23 | E24: =E16+E18+E19+E20+E21+E22+E23 | F24: =F16+F18+F19+F20+F21+F22+F23 | G24: =G16+G18+G19+G20+G21+G22+G23 | H24: =H16+H18+H19+H20+H21+H22+H23 | I24: =I16+I18+I19+I20+I21+I22+I23 | J24: =J16+J18+J19+J20+J21+J22+J23 | K24: Operating profit + all printed add-backs
A25: Adjusted EBITDA — as reported by the company [D] | B25: 422 | C25: 476 | D25: 536 | E25: 130 | F25: 142 | G25: 272 | H25: 140 | I25: 153 | J25: 293 | K25: FY/Q1: Form 10/A "Segment Adjusted EBITDA" (10-exclusion def.); Q2/6M: 10-Q (6-exclusion def.). 10Q_Q2-2026; Form10A_2026-05-27
A26: CHECK uniform build − reported | B26: =B24-B25 | C26: =C24-C25 | D26: n/a | E26: =E24-E25 | F26: =F24-F25 | G26: =G24-G25 | H26: =H24-H25 | I26: =I24-I25 | J26: =J24-J25 | K26: n/a: segment split of FY2025 "Other" ($2m total) not legible | Z26: CHECK
A27: Adjusted EBITDA margin [C] | B27: =B25/B6 | C27: =C25/C6 | D27: =D25/D6 | E27: =E25/E6 | F27: =F25/F6 | G27: =G25/G6 | H27: =H25/H6 | I27: =I25/I6 | J27: =J25/J6 | K27: [C]
A28: Adjusted EBITDA growth y/y [C] | C28: =C25/B25-1 | D28: =D25/C25-1 | H28: =H25/E25-1 | I28: =I25/F25-1 | J28: =J25/G25-1 | K28: [C]
A29: Incremental Adj. EBITDA margin (Δ EBITDA / Δ revenue) [C] | C29: =(C25-B25)/(C6-B6) | D29: =(D25-C25)/(D6-C6) | H29: =(H25-E25)/(H6-E6) | I29: =(I25-F25)/(I6-F6) | J29: =(J25-G25)/(J6-G6) | K29: [C]
A30: Cash operating costs = revenue − Adj. EBITDA [C] | B30: =B6-B25 | C30: =C6-C25 | D30: =D6-D25 | E30: =E6-E25 | F30: =F6-F25 | G30: =G6-G25 | H30: =H6-H25 | I30: =I6-I25 | J30: =J6-J25 | K30: [C]
A31: D&A % revenue [C] | B31: =(B18+B19)/B6 | C31: =(C18+C19)/C6 | D31: =(D18+D19)/D6 | E31: =(E18+E19)/E6 | F31: =(F18+F19)/F6 | G31: =(G18+G19)/G6 | H31: =(H18+H19)/H6 | I31: =(I18+I19)/I6 | J31: =(J18+J19)/J6 | K31: [C]
A32: SBC % revenue [C] | B32: =B20/B6 | C32: =C20/C6 | D32: =D20/D6 | E32: =E20/E6 | F32: =F20/F6 | G32: =G20/G6 | H32: =H20/H6 | I32: =I20/I6 | J32: =J20/J6 | K32: [C]
A34: B2B segment (Marketing & Sales; Strategy & Planning)
A35: Revenue [D] | B35: 557 | C35: 574 | D35: 608 | E35: 145 | F35: 150 | G35: 295 | H35: 157 | I35: 156 | J35: 313 | K35: 10Q_Q2-2026; Form10A_2026-05-27
A36: Revenue growth y/y [C] | C36: =C35/B35-1 | D36: =D35/C35-1 | H36: =H35/E35-1 | I36: =I35/F35-1 | J36: =J35/G35-1 | K36: [C]
A37: Subscription [D] | B37: 422 | C37: 460 | D37: 499 | E37: 118 | F37: 124 | G37: 242 | H37: 130 | I37: 131 | J37: 261 | K37: 10Q_Q2-2026; Form10A_2026-05-27
A38: Non-subscription [D] | B38: 135 | C38: 114 | D38: 109 | E38: 27 | F38: 26 | G38: 53 | H38: 27 | I38: 25 | J38: 52 | K38: 10Q_Q2-2026; Form10A_2026-05-27
A39: Subscription share [C] | B39: =B37/B35 | C39: =C37/C35 | D39: =D37/D35 | E39: =E37/E35 | F39: =F37/F35 | G39: =G37/G35 | H39: =H37/H35 | I39: =I37/I35 | J39: =J37/J35 | K39: [C]
A40: U.S. [D] | B40: 433 | C40: 445 | D40: 480 | E40: 114 | F40: 119 | G40: 233 | H40: 123 | I40: 124 | J40: 247 | K40: 10Q_Q2-2026; Form10A_2026-05-27
A41: International [D] | B41: 124 | C41: 129 | D41: 128 | E41: 31 | F41: 31 | G41: 62 | H41: 34 | I41: 32 | J41: 66 | K41: 10Q_Q2-2026; Form10A_2026-05-27
A42: International growth y/y [C] | C42: =C41/B41-1 | D42: =D41/C41-1 | H42: =H41/E41-1 | I42: =I41/F41-1 | J42: =J41/G41-1 | K42: [C]
...

Sheet Segments
A1: Segments — as defined in each filing (never recast backwards)
A2: Form 10/A: segment operating profit (ASU 2023-07 format). 10-Q/8-K: Adjusted EBITDA as segment measure from Q2-2026 (prior periods recast BY THE COMPANY). Bases not comparable — see Accounting Notes.
A4: Line item (verbatim caption) | B4: FY2023 | C4: FY2024 | D4: FY2025 | E4: Q1-2025 | F4: Q2-2025 | G4: 6M-2025 | H4: Q1-2026 | I4: Q2-2026 | J4: 6M-2026 | K4: Source (doc p.)
A5: 10Q_Q2-2026 · Note 7 Segment and Geographic Information - segment table
A6: CARFAX: Revenue | F6: 289 | G6: 564 | I6: 312 | J6: 610 | K6: 10Q_Q2-2026 p14
A7: B2B: Revenue | F7: 150 | G7: 295 | I7: 156 | J7: 313 | K7: 10Q_Q2-2026 p14
A8: Corporate: Revenue | F8: 0 | G8: 0 | I8: 0 | J8: 0 | K8: 10Q_Q2-2026 p14
A9: Total: Revenue | F9: 439 | G9: 859 | I9: 468 | J9: 923 | K9: 10Q_Q2-2026 p14
A10: CARFAX: Less: segment expenses (1) | F10: 147 | G10: 292 | I10: 159 | J10: 317 | K10: 10Q_Q2-2026 p14
A11: B2B: Less: segment expenses (1) | F11: 101 | G11: 202 | I11: 103 | J11: 211 | K11: 10Q_Q2-2026 p14
A12: Corporate: Less: segment expenses (1) | F12: 3 | G12: 8 | I12: 4 | J12: 9 | K12: 10Q_Q2-2026 p14
A13: Total: Less: segment expenses (1) | F13: 251 | G13: 502 | I13: 266 | J13: 537 | K13: 10Q_Q2-2026 p14
A14: CARFAX: Adjusted EBITDA | F14: 142 | G14: 272 | I14: 153 | J14: 293 | K14: 10Q_Q2-2026 p14
A15: B2B: Adjusted EBITDA | F15: 49 | G15: 93 | I15: 53 | J15: 102 | K15: 10Q_Q2-2026 p14
A16: Corporate: Adjusted EBITDA | F16: -3 | G16: -8 | I16: -4 | J16: -9 | K16: 10Q_Q2-2026 p14
A17: Total: Adjusted EBITDA | F17: 188 | G17: 357 | I17: 202 | J17: 386 | K17: 10Q_Q2-2026 p14
A18: 10Q_Q2-2026 · Note 7 Segment and Geographic Information
A19: Reportable segments (count): CARFAX and B2B; Corporate category not allocated | I19: 2 | K19: 10Q_Q2-2026 p14
A20: 10Q_Q2-2026 · MD&A Segment Results - CARFAX
A21: CARFAX: Revenue | F21: 289 | G21: 564 | I21: 312 | J21: 610 | K21: 10Q_Q2-2026 p28
A22: CARFAX: Revenue - Change % | I22: 8 | J22: 8 | K22: 10Q_Q2-2026 p28
A23: CARFAX: Subscription revenue | F23: 234 | G23: 459 | I23: 252 | J23: 494 | K23: 10Q_Q2-2026 p28
A24: CARFAX: Subscription revenue - Change % | I24: 8 | J24: 8 | K24: 10Q_Q2-2026 p28
A25: CARFAX: Non-subscription revenue | F25: 55 | G25: 105 | I25: 60 | J25: 116 | K25: 10Q_Q2-2026 p28
A26: CARFAX: Non-subscription revenue - Change % | I26: 9 | J26: 10 | K26: 10Q_Q2-2026 p28
A27: CARFAX: % of total revenue: Subscription revenue | F27: 81 | G27: 81 | I27: 81 | J27: 81 | K27: 10Q_Q2-2026 p28
A28: CARFAX: % of total revenue: Non-subscription revenue | F28: 19 | G28: 19 | I28: 19 | J28: 19 | K28: 10Q_Q2-2026 p28
A29: CARFAX: U.S. revenue | F29: 246 | G29: 482 | I29: 265 | J29: 518 | K29: 10Q_Q2-2026 p28
A30: CARFAX: U.S. revenue - Change % | I30: 8 | J30: 7 | K30: 10Q_Q2-2026 p28
A31: CARFAX: International revenue | F31: 43 | G31: 82 | I31: 47 | J31: 92 | K31: 10Q_Q2-2026 p28
A32: CARFAX: International revenue - Change % | I32: 9 | J32: 12 | K32: 10Q_Q2-2026 p28
A33: CARFAX: % of total revenue: U.S. revenue | F33: 85 | G33: 85 | I33: 85 | J33: 85 | K33: 10Q_Q2-2026 p28
A34: CARFAX: % of total revenue: International revenue | F34: 15 | G34: 15 | I34: 15 | J34: 15 | K34: 10Q_Q2-2026 p28
A35: CARFAX: Adjusted EBITDA | F35: 142 | G35: 272 | I35: 153 | J35: 293 | K35: 10Q_Q2-2026 p28
A36: CARFAX: Adjusted EBITDA - Change % | I36: 8 | J36: 8 | K36: 10Q_Q2-2026 p28
A37: CARFAX: %Adjusted EBITDA margin | F37: 49 | G37: 48 | I37: 49 | J37: 48 | K37: 10Q_Q2-2026 p28
A38: 10Q_Q2-2026 · MD&A Segment Results - B2B
A39: B2B: Revenue | F39: 150 | G39: 295 | I39: 156 | J39: 313 | K39: 10Q_Q2-2026 p29
A40: B2B: Revenue - Change % | I40: 4 | J40: 6 | K40: 10Q_Q2-2026 p29
A41: B2B: Subscription revenue | F41: 124 | G41: 242 | I41: 131 | J41: 261 | K41: 10Q_Q2-2026 p29
...

Sheet Revenue Detail
A1: Revenue disaggregation — as printed
A2: No revenue by brand/product or by B2B business line is disclosed. Geography = U.S. vs International only.
A4: Line item (verbatim caption) | B4: FY2023 | C4: FY2024 | D4: FY2025 | E4: Q1-2025 | F4: Q2-2025 | G4: 6M-2025 | H4: Q1-2026 | I4: Q2-2026 | J4: 6M-2026 | K4: Source (doc p.)
A5: Form10A_2026-05-27 · MD&A Revenue (three months ended March 31)
A6: Revenue | E6: 420 | H6: 455 | K6: Form10A_2026-05-27 p346
A7: Revenue % Change | H7: 8 | K7: Form10A_2026-05-27 p346
A8: Subscription revenue | E8: 343 | H8: 372 | K8: Form10A_2026-05-27 p346
A9: Subscription revenue % Change | H9: 8 | K9: Form10A_2026-05-27 p346
A10: Non - subscription revenue | E10: 77 | H10: 83 | K10: Form10A_2026-05-27 p346
A11: Non - subscription revenue % Change | H11: 7 | K11: Form10A_2026-05-27 p346
A12: % of total revenue: Subscription revenue | E12: 82 | H12: 82 | K12: Form10A_2026-05-27 p346
A13: U.S. revenue % Change | H13: 7 | K13: Form10A_2026-05-27 p346
A14: % of total revenue: Non - subscription revenue | E14: 18 | H14: 18 | K14: Form10A_2026-05-27 p346
A15: International revenue % Change | H15: 12 | K15: Form10A_2026-05-27 p346
A16: U.S. revenue | E16: 350 | H16: 376 | K16: Form10A_2026-05-27 p346
A17: International revenue | E17: 70 | H17: 79 | K17: Form10A_2026-05-27 p346
A18: % of total revenue: U.S. revenue | E18: 83 | H18: 83 | K18: Form10A_2026-05-27 p346
A19: % of total revenue: International revenue | E19: 17 | H19: 17 | K19: Form10A_2026-05-27 p346
A20: 10Q_Q2-2026 · Note 7 revenue disaggregated by revenue type
A21: CARFAX: Subscription | F21: 234 | G21: 459 | I21: 252 | J21: 494 | K21: 10Q_Q2-2026 p15
A22: B2B: Subscription | F22: 124 | G22: 242 | I22: 131 | J22: 261 | K22: 10Q_Q2-2026 p15
A23: Total: Subscription | F23: 358 | G23: 701 | I23: 383 | J23: 755 | K23: 10Q_Q2-2026 p15
A24: CARFAX: Non-subscription | F24: 55 | G24: 105 | I24: 60 | J24: 116 | K24: 10Q_Q2-2026 p15
A25: B2B: Non-subscription | F25: 26 | G25: 53 | I25: 25 | J25: 52 | K25: 10Q_Q2-2026 p15
A26: Total: Non-subscription | F26: 81 | G26: 158 | I26: 85 | J26: 168 | K26: 10Q_Q2-2026 p15
A27: CARFAX: Total revenue | F27: 289 | G27: 564 | I27: 312 | J27: 610 | K27: 10Q_Q2-2026 p15
A28: B2B: Total revenue | F28: 150 | G28: 295 | I28: 156 | J28: 313 | K28: 10Q_Q2-2026 p15
A29: Total: Total revenue | F29: 439 | G29: 859 | I29: 468 | J29: 923 | K29: 10Q_Q2-2026 p15
A30: CARFAX: Timing of revenue recognition - Services transferred at a point in time | F30: 55 | G30: 105 | I30: 60 | J30: 116 | K30: 10Q_Q2-2026 p15
A31: B2B: Timing of revenue recognition - Services transferred at a point in time | F31: 26 | G31: 53 | I31: 25 | J31: 52 | K31: 10Q_Q2-2026 p15
A32: Total: Timing of revenue recognition - Services transferred at a point in time | F32: 81 | G32: 158 | I32: 85 | J32: 168 | K32: 10Q_Q2-2026 p15
... A35: Total: Timing of revenue recognition - Services transferred over time | F35: 358 | G35: 701 | I35: 383 | J35: 755 | K35: 10Q_Q2-2026 p15
A36: 10Q_Q2-2026 · Note 7 revenue by geographic region
A37: U.S. | F37: 365 | G37: 715 | I37: 389 | J37: 765 | K37: 10Q_Q2-2026 p15
A38: International | F38: 74 | G38: 144 | I38: 79 | J38: 158 | K38: 10Q_Q2-2026 p15
A39: Total | F39: 439 | G39: 859 | I39: 468 | J39: 923 | K39: 10Q_Q2-2026 p15
A40: 10Q_Q2-2026 · MD&A Revenue table (total company)
A41: Revenue | F41: 439 | G41: 859 | I41: 468 | J41: 923 | K41: 10Q_Q2-2026 p27
A42: Revenue - Change % | I42: 7 | J42: 7 | K42: 10Q_Q2-2026 p27
A43: Subscription revenue | F43: 358 | G43: 701 | I43: 383 | J43: 755 | K43: 10Q_Q2-2026 p27
...

Sheet Adjusted Non-GAAP
A1: Non-GAAP / APMs — as printed per document
A2: Adjusted EBITDA definition: 10 exclusions (Form 10, 10/A) vs 6 (10-Q, 8-K). 8-K Exhibit 5 add-back lines corrupted in source text — 10-Q used. Unaudited.
A4: Line item (verbatim caption) | B4: FY2023 | C4: FY2024 | D4: FY2025 | E4: Q1-2025 | F4: Q2-2025 | G4: 6M-2025 | H4: Q1-2026 | I4: Q2-2026 | J4: 6M-2026 | K4: Source (doc p.)
A5: 10Q_Q2-2026 · Note 7 reconciliation of GAAP Net income to Adjusted EBITDA
A6: Net income | F6: 65 | G6: 123 | I6: 53 | J6: 108 | K6: 10Q_Q2-2026 p15
A7: Interest expense, net | F7: 4 | G7: 7 | I7: 7 | J7: 10 | K7: 10Q_Q2-2026 p15
A8: Provision for taxes on income | F8: 27 | G8: 50 | I8: 22 | J8: 45 | K8: 10Q_Q2-2026 p15
A9: Depreciation and amortization | F9: 77 | G9: 155 | I9: 77 | J9: 155 | K9: 10Q_Q2-2026 p15
A10: Stock-based compensation | F10: 4 | G10: 9 | I10: 5 | J10: 9 | K10: 10Q_Q2-2026 p15
A11: Transaction costs | F11: 2 | G11: 2 | I11: 36 | J11: 57 | K11: 10Q_Q2-2026 p15
A12: Employee severance charges and other | F12: 9 | G12: 11 | I12: 2 | J12: 2 | K12: 10Q_Q2-2026 p15
A13: Adjusted EBITDA | F13: 188 | G13: 357 | I13: 202 | J13: 386 | K13: 10Q_Q2-2026 p15
A14: 10Q_Q2-2026 · MD&A Non-GAAP reconciliation of Net income to Adjusted EBITDA by segment
A15: Total: Net income (GAAP) | F15: 65 | G15: 123 | I15: 53 | J15: 108 | K15: 10Q_Q2-2026 p24; 10Q_Q2-2026 p25
A16: Total: Interest expense, net | F16: 4 | G16: 7 | I16: 7 | J16: 10 | K16: 10Q_Q2-2026 p24; 10Q_Q2-2026 p25
A17: Total: Provision for income taxes | F17: 27 | G17: 50 | I17: 22 | J17: 45 | K17: 10Q_Q2-2026 p24; 10Q_Q2-2026 p25
A18: CARFAX: Operating profit (GAAP) | F18: 89 | G18: 166 | I18: 101 | J18: 190 | K18: 10Q_Q2-2026 p24; 10Q_Q2-2026 p25
A19: CARFAX: Adjusted to add: Amortization of intangibles | F19: 48 | G19: 95 | I19: 48 | J19: 95 | K19: 10Q_Q2-2026 p24; 10Q_Q2-2026 p25
A20: CARFAX: Adjusted to add: Depreciation | F20: 2 | G20: 5 | I20: 2 | J20: 5 | K20: 10Q_Q2-2026 p24; 10Q_Q2-2026 p25
A21: CARFAX: Adjusted to add: Stock-based compensation | F21: 2 | G21: 5 | I21: 2 | J21: 3 | K21: 10Q_Q2-2026 p24; 10Q_Q2-2026 p25
A22: CARFAX: Adjusted to add: Transaction costs | F22: 0 | G22: 0 | I22: 0 | J22: 0 | K22: 10Q_Q2-2026 p24; 10Q_Q2-2026 p25
A23: CARFAX: Adjusted to add: Employee severance charges and other | F23: 1 | G23: 1 | I23: 0 | J23: 0 | K23: 10Q_Q2-2026 p24; 10Q_Q2-2026 p25
A24: CARFAX: Adjusted EBITDA | F24: 142 | G24: 272 | I24: 153 | J24: 293 | K24: 10Q_Q2-2026 p24; 10Q_Q2-2026 p25
A25: CARFAX: % Adjusted EBITDA margin | F25: 49 | G25: 48 | I25: 49 | J25: 48 | K25: 10Q_Q2-2026 p24; 10Q_Q2-2026 p25
A26: B2B: Operating profit (GAAP) | F26: 16 | G26: 30 | I26: 3 | J26: 8 | K26: 10Q_Q2-2026 p24; 10Q_Q2-2026 p25
... A48: Total: % Adjusted EBITDA margin | F48: 43 | G48: 42 | I48: 43 | J48: 42 | K48: 10Q_Q2-2026 p24; 10Q_Q2-2026 p25
A49: 10Q_Q2-2026 · MD&A Non-GAAP reconciliation by segment
A50: Corporate: % Adjusted EBITDA margin (printed N/M) | F50: N/M | G50: N/M | I50: N/M | J50: N/M | K50: 10Q_Q2-2026 p25
A51: 10Q_Q2-2026 · MD&A Free cash flow reconciliation (six months)
A52: Cash provided by operating activities | G52: 233 | J52: 189 | K52: 10Q_Q2-2026 p26
A53: Capital expenditures | G53: -8 | J53: -12 | K53: 10Q_Q2-2026 p26
A54: Free cash flow | G54: 225 | J54: 177 | K54: 10Q_Q2-2026 p26
A55: 10Q_Q2-2026 · MD&A Results of operations
A56: Adjusted EBITDA | F56: 188 | G56: 357 | I56: 202 | J56: 386 | K56: 10Q_Q2-2026 p26
A57: Adjusted EBITDA - Change $ | I57: 14 | J57: 29 | K57: 10Q_Q2-2026 p26
A58: Adjusted EBITDA - Change % | I58: 7 | J58: 8 | K58: 10Q_Q2-2026 p26
A59: %Net income margin | F59: 15 | G59: 14 | I59: 11 | J59: 12 | K59: 10Q_Q2-2026 p26
A60: %Adjusted EBITDA margin | F60: 43 | G60: 42 | I60: 43 | J60: 42 | K60: 10Q_Q2-2026 p26
A61: 8K_2026-08-07 · Financial Summary table (Profitability / Non-GAAP / Cash flow)
A62: Operating profit | F62: 96 | G62: 180 | I62: 82 | J62: 163 | K62: 8K_2026-08-07 p2
...

Sheet Operating KPIs
A1: Operating KPIs & guidance — as printed
A2: Definitions per source; [D] filings, release and decks. Guidance dated 2026-08-07.
A4: Line item (verbatim caption) | B4: FY2023 | C4: FY2024 | D4: FY2025 | E4: Q1-2025 | F4: Q1-2026 | G4: Q2-2026 | H4: 6M-2026 | I4: FY2026E | J4: Source (doc p.)
A5: Form10A_2026-05-27 · MD&A Results of operations
A6: % Operating profit margin | E6: 20 | F6: 18 | J6: Form10A_2026-05-27 p346
A7: 10Q_Q2-2026 · MD&A Revenue drivers (approximate, as printed)
A8: Revenue increase from price increases (approximately) | G8: 16 | H8: 36 | J8: 10Q_Q2-2026 p27
A9: Revenue increase from continued new business growth (approximately) | G9: 8 | H9: 20 | J9: 10Q_Q2-2026 p27
A10: 10Q_Q2-2026 · Note 2 Unearned revenue & RPO
A11: Revenues recognized included in unearned revenue balance at beginning of period | H11: 60 | J11: 10Q_Q2-2026 p10
A12: Remaining performance obligations (aggregate transaction price) | H12: 102 | J12: 10Q_Q2-2026 p10
A13: 10Q_Q2-2026 · MD&A Overview - CARFAX (as of December 31, 2025)
A14: CARFAX dealer customers (over) | D14: 40000 | J14: 10Q_Q2-2026 p19
A15: 10Q_Q2-2026 · MD&A Overview - B2B (as of December 31, 2025, internal data)
A16: Share of top 40 global carmakers served | D16: 100 | J16: 10Q_Q2-2026 p19
A17: Share of top 100 automotive suppliers served | D17: 94 | J17: 10Q_Q2-2026 p19
A18: Share of top 10 investment banks served | D18: 100 | J18: 10Q_Q2-2026 p19
A19: 10Q_Q2-2026 · MD&A Key factors (as of December 31, 2025)
A20: CARFAX Car Care consumers (over) | D20: 53000000 | J20: 10Q_Q2-2026 p21
A21: 10Q_Q2-2026 · MD&A Basis of presentation
A22: Non-recurring stand-alone/TSA transition costs - range (printed $75 million to $110 million) | I22: 75-110 | J22: 10Q_Q2-2026 p23
A23: 8K_2026-08-07 · Release highlights (comparisons to Q2 2025)
A24: Total revenue growth | G24: 7 | J24: 8K_2026-08-07 p1
A25: CARFAX revenue growth year-over-year | G25: 8 | J25: 8K_2026-08-07 p1
A26: Subscription revenue growth | G26: 7 | J26: 8K_2026-08-07 p1
A27: Non-subscription revenue growth | G27: 5 | J27: 8K_2026-08-07 p1
A28: B2B segment revenue growth | G28: 4 | J28: 8K_2026-08-07 p1
A29: Net income margin | G29: 11 | J29: 8K_2026-08-07 p1
A30: Adjusted EBITDA growth | G30: 7 | J30: 8K_2026-08-07 p1
A31: Adjusted EBITDA margin | G31: 43 | J31: 8K_2026-08-07 p1
A32: Quarterly cash dividend per share (initiated) | G32: 0.06 | J32: 8K_2026-08-07 p1
A33: 8K_2026-08-07 · Outlook - Full-Year 2026 Guidance (issued August 7, 2026)
A34: Revenue (printed $1,870 - $1,885 million) | I34: 1870-1885 | J34: 8K_2026-08-07 p3
A35: Revenue - low end | I35: 1870 | J35: 8K_2026-08-07 p3
A36: Revenue - high end | I36: 1885 | J36: 8K_2026-08-07 p3
A37: Revenue Growth (printed 6.9% - 7.7%) | I37: 6.9-7.7 | J37: 8K_2026-08-07 p3
A38: Adjusted EBITDA (printed $745 - $760 million) | I38: 745-760 | J38: 8K_2026-08-07 p3
A39: Adjusted EBITDA - low end | I39: 745 | J39: 8K_2026-08-07 p3
A40: Adjusted EBITDA - high end | I40: 760 | J40: 8K_2026-08-07 p3
A41: Adjusted EBITDAMargin (printed ~40%) | I41: 40 | J41: 8K_2026-08-07 p3
...

Sheet Debt Schedule
A1: Debt — instrument by instrument
A2: As printed; see notes_NOTES.md for unreadable cells and tables that do not foot.
A4: Line item (verbatim caption) | B4: FY2023 | C4: FY2024 | D4: FY2025 | E4: Q1-2025 | F4: 6M-2025 | G4: Q1-2026 | H4: Q2-2026 | I4: 6M-2026 | J4: Q3-2026 | K4: Source (doc p.)
A5: Form10A_2026-05-27 · Canada Carfax Loan (related party; IHS Canada; dated 2018-10-01; matures 2027-10-05)
A6: principal amount at origination (CAD millions; printed CAD $403 million) | G6: 403 | K6: Form10A_2026-05-27 p435
A7: Form10A_2026-05-27 · Canada Carfax Loan
A8: interest rate per annum | G8: 6 | K8: Form10A_2026-05-27 p435
A9: outstanding loan balance payable to S&P Global inclusive of accrued interest (Due to related parties - non-current) | D9: 230 | G9: 227 | K9: Form10A_2026-05-27 p435
A10: outstanding loan balance payable to S&P Global inclusive of accrued interest (Due to related parties non-current) | C10: 236 | D10: 230 | K10: Form10A_2026-05-27 p466
A11: related party interest expense | B11: 18 | C11: 17 | D11: 14 | E11: 4 | G11: 3 | K11: Form10A_2026-05-27 p435; Form10A_2026-05-27 p466
A12: voluntary prepayments on principal | E12: 10 | G12: 0 | K12: Form10A_2026-05-27 p435
A13: voluntary prepayments on the principal balance | C13: 45 | D13: 18 | K13: Form10A_2026-05-27 p466
A14: payments of interest | B14: 18 | C14: 17 | D14: 14 | E14: 3 | G14: 3 | K14: Form10A_2026-05-27 p435; Form10A_2026-05-27 p466
A15: Form10A_2026-05-27 · Europe Carfax Loan (receivable from IHS Holdings; matured 2026-02-14; 6M LIBOR+0.5%)
A16: maximum aggregate principal (EUR millions; printed EUR 10 million) | G16: 10 | K16: Form10A_2026-05-27 p436
A17: Form10A_2026-05-27 · Subsequent event
A18: revolving credit facility entered 2026-05-06 (the Credit Facility) | G18: 500 | K18: Form10A_2026-05-27 p437
A19: Form10A_2026-05-27 · Europe Carfax Loan (receivable)
A20: outstanding loan receivable from S&P Global inclusive of accrued interest (Due from related parties - non-current) | C20: 4 | K20: Form10A_2026-05-27 p467
A21: cash received related to principal and interest (repaid in full 2025-11-30) | D21: 5 | K21: Form10A_2026-05-27 p467
A22: Form10A_2026-05-27 · Capitalization - Actual
A23: Cash and cash equivalents | G23: 122 | K23: Form10A_2026-05-27 p331
A24: Due to related parties – non-current (1) | G24: 227 | K24: Form10A_2026-05-27 p331
A25: Total indebtedness | G25: 227 | K25: Form10A_2026-05-27 p331
A26: Accumulated other comprehensive (loss) income | G26: -3 | K26: Form10A_2026-05-27 p331
A27: Parent company investment (4) | G27: 11586 | K27: Form10A_2026-05-27 p331
A28: Total equity | G28: 11583 | K28: Form10A_2026-05-27 p331
A29: Total capitalization | G29: 11810 | K29: Form10A_2026-05-27 p331
A30: Form10A_2026-05-27 · Capitalization - Pro Forma
A31: Cash and cash equivalents | G31: 200 | K31: Form10A_2026-05-27 p331
A32: Long-term debt (2) | G32: 1981 | K32: Form10A_2026-05-27 p331
A33: Total indebtedness | G33: 1981 | K33: Form10A_2026-05-27 p331
A34: Common stock par value $0.01 per share (3) | G34: 3 | K34: Form10A_2026-05-27 p331
A35: Additional paid-in capital (4) | G35: 9927 | K35: Form10A_2026-05-27 p331
A36: Accumulated other comprehensive (loss) income | G36: -3 | K36: Form10A_2026-05-27 p331
A37: Total equity | G37: 9927 | K37: Form10A_2026-05-27 p331
A38: Total capitalization | G38: 11908 | K38: Form10A_2026-05-27 p331
A39: Form10A_2026-05-27 · Revolving credit facility
A40: revolving credit facility capacity (undrawn at Separation) | G40: 500 | K40: Form10A_2026-05-27 p337
A41: deferred debt issuance costs - credit facility (Other non-current assets) | G41: 3 | K41: Form10A_2026-05-27 p337
...

Sheet Tax Reconciliation
A1: Income taxes — ETR reconciliation, current/deferred, DTA/DTL
A2: As printed; see notes_NOTES.md for unreadable cells and tables that do not foot.
A4: Line item (verbatim caption) | B4: FY2023 | C4: FY2024 | D4: FY2025 | E4: Q1-2025 | F4: Q2-2025 | G4: 6M-2025 | H4: Q1-2026 | I4: Q2-2026 | J4: 6M-2026 | K4: Source (doc p.)
A5: Form10A_2026-05-27 · Income before taxes by source
A6: Domestic operations | B6: 184 | C6: 225 | D6: 276 | K6: Form10A_2026-05-27 p455
A7: Foreign operations | B7: 40 | C7: 59 | D7: 50 | K7: Form10A_2026-05-27 p455
A8: Total income before taxes | B8: 224 | C8: 284 | D8: 326 | K8: Form10A_2026-05-27 p455
A9: Form10A_2026-05-27 · Provision for taxes on income
A10: Federal: Current | B10: 90 | C10: 103 | D10: 110 | K10: Form10A_2026-05-27 p455
A11: Federal: Deferred | B11: -59 | C11: -64 | D11: -62 | K11: Form10A_2026-05-27 p455
A12: Total federal | C12: 39 | D12: 48 | K12: Form10A_2026-05-27 p455
A13: Foreign: Current | D13: 30 | K13: Form10A_2026-05-27 p455
